Workbook

Sheet Partici
A1: N°
A2: 1 | B2: CAMPEON DE CAMPEONES
A3: 2 | B3: FERNANDA
A4: 3 | B4: TRINIDAD
A5: 4 | B5: OVAYORK
A6: 5 | B6: SALVAYORK
A7: 6 | B7: KING JORANTO
A8: 7 | B8: TOCOCO
A9: 8 | B9: AUMENTA MEDINA
A10: 9 | B10: MAGICO MEDINA
A11: 10 | B11: KOKE
A12: 11 | B12: SERVIFRENOS
A13: 12 | B13: ALF
... A28: 27 | B28: STORMILORD
A29: 28
A30: 29
A31: 30
A32: 31
A33: 32
A34: DIARIA DIA 1 | C34: DIARIA DIA 2 | D34: DIARIA DIA 3 | E34: DIARIA DIA 4 | F34: DIARIA DIA 5 | G34: DIARIA DIA 6 | H34: DIARIA DIA 7 | I34: DIARIA DIA 8 | J34: DIARIA DIA 9 | K34: DIARIA DIA 10 | L34: DIARIA DIA 11 | M34: DIARIA DIA 12 | N34: DIARIA DIA 13
A35: 27
A36: 28
A37: 29
A38: 30
A39: 31
A40: 32
A41: 33
A42: 34
A43: 35
A44: 36
A45: 37
A46: 38
... A68: 60

Sheet Tabla
AF3: 1 | AK3: 2 | AP3: 3 | AU3: 4 | AZ3: 5 | BE3: 6 | BJ3: 7 | BO3: 8 | BT3: 9 | BY3: 10 | CD3: 11 | CI3: 12 | CN3: 13
A4: POZO PREMIO: $ 195.000 10% TABLERISTA: $ 19.500 PRIMER LUGAR: $ 130.000 SEGUNDO LUGAR: $ 45.500 | AF4: POLLA DIARIA: ENCUENTRO HIPICO HCH VALOR: $ 4000 | AK4: POLLA DIARIA: ENCUENTRO HIPICO CHS VALOR: $ 4000 | AP4: POLLA DIARIA: ENCUENTRO HIPICO HCH VALOR: $ 7000 | AU4: POLLA DIARIA: ENCUENTRO HIPICO CHS VALOR: $ 4000 | AZ4: POLLA DIARIA: ENCUENTRO HIPICO HCH VALOR: $ 4000 | BE4: POLLA DIARIA: ENCUENTRO HIPICO CHS VALOR: $ 4000 | BJ4: POLLA DIARIA: ENCUENTRO HIPICO HCH VALOR: $ 4000 | BO4: POLLA DIARIA: ENCUENTRO HIPICO CHS VALOR: $ 4000 | BT4: POLLA DIARIA: ENCUENTRO HIPICO CHS VALOR: $ 4000 | BY4: POLLA DIARIA: ENCUENTRO HIPICO HCH VALOR: $ 4000 | CD4: POLLA DIARIA: ENCUENTRO HIPICO CHS VALOR: $ 4000 | CI4: POLLA DIARIA: ENCUENTRO HIPICO HCH VALOR: $ 4000 | CN4: POLLA DIARIA: ENCUENTRO HIPICO CHS VALOR: $ 4000
AE5: DIARIAS
AF6: POZO PREMIOS: $ 48.000 10% TABLERISTA: $ 5.000 Primero: $ 34.000 Segundo: $ 9.000 | AK6: POZO PREMIOS: $ 48.000 10% TABLERISTA: $ 5.000 Primero: $ 34.000 Segundo: $ 9.000 | AP6: POZO PREMIOS: $ 105.000 10% TABLERISTA: $ 11.000 Primero: $ 75.000 Segundo: $ 19.000 | AU6: POZO PREMIOS: $ 52.000 10% TABLERISTA: $ 5.000 Primero: $ 37.000 Segundo: $ 10.000 | AZ6: POZO PREMIOS: $ 64.000 10% TABLERISTA: $ 6.400 Primero: $ 45.000 Segundo: $ 12.600 | BE6: POZO PREMIOS: $ 72.000 10% TABLERISTA: $ 7.200 Primero: $ 50.000 Segundo: $14.800 | BJ6: POZO PREMIOS: $ 96.000 10% TABLERISTA: $ 9.600 Primero: $ 63.200 Segundo: $23.200 | BO6: POZO PREMIOS: $ 88.000 10% TABLERISTA: $ 8.000 Primero: $ 60.000 Segundo: $20.000 | BT6: PREMIOS: Primero: $ Segundo: $ | BY6: PREMIOS: Primero: $ Segundo: $ | CD6: PREMIOS: Primero: $ Segundo: $ | CI6: PREMIOS: Primero: $ Segundo: $ | CN6: PREMIOS: Primero: $ Segundo: $
A7: LUGAR | B7: STUD | C7: 05-mar | D7: 06-mar | E7: 21-ene | F7: 22-ene | G7: 23-ene | H7: 24-ene | I7: 26-ene | J7: 27-ene | K7: 29-ene | L7: 30-ene | M7: 31-ene | N7: 01-feb | O7: 24-dic | P7: 28-jul | Q7: 29-jul | R7: 04-ene | S7: 10-jul17 | T7: 10-jul18 | U7: 10-jul19 | V7: 10-jul20 | W7: TOTAL | X7: DIFERENCIA | Z7: SOY FICHA | AA7: 34.8 | AB7: 31.3 | AC7: 79.5 | AD7: 138.8 | AF7: LUGAR | AG7: STUD | AH7: TOTAL | AI7: Diferencia | AK7: LUGAR | AL7: STUD | AM7: TOTAL | AN7: Diferencia | AP7: LUGAR | AQ7: STUD | AR7: TOTAL | AS7: Diferencia | AU7: LUGAR | AV7: STUD | AW7: TOTAL | AX7: Diferencia | AZ7: LUGAR | BA7: STUD | BB7: TOTAL | BC7: Diferencia | BE7: LUGAR | BF7: STUD | BG7: TOTAL | BH7: Diferencia | BJ7: LUGAR | BK7: STUD | BL7: TOTAL | BM7: Diferencia | BO7: LUGAR | BP7: STUD | BQ7: TOTAL | BR7: Diferencia | BT7: LUGAR | BU7: STUD | BV7: TOTAL | BW7: Diferencia | BY7: LUGAR | BZ7: STUD | CA7: TOTAL | CB7: Diferencia | CD7: LUGAR | CE7: STUD | CF7: TOTAL | CG7: Diferencia | CI7: LUGAR | CJ7: STUD | CK7: TOTAL | CL7: Diferencia | CN7: LUGAR | CO7: STUD | CP7: TOTAL | CQ7: Diferencia
A8: 1 | B8: =+Partici!B15 -> SEA COURT 1 | C8: ='DIA 1'!$AC$33 -> 1.1 | D8: ='DIA 2'!$AC$33 -> 0 | E8: ='DIA 3'!$AC$33 -> 0 | F8: ='DIA 4'!$AC$33 -> 0 | G8: ='DIA 5'!$AC$33 -> 0 | H8: ='DIA 6'!$AC$33 -> 0 | I8: ='DIA 7'!$AC$33 -> 0 | J8: ='DIA 8'!$AC$33 -> 0 | K8: ='DIA 9'!$AC$33 -> 0 | L8: ='DIA 10'!$AC$33 -> 0 | M8: ='DIA 11'!$AC$33 -> 0 | N8: ='DIA 12'!$AC$33 -> 0 | O8: ='24 12 23. CLUB'!$AC$33 -> 0 | P8: ='Dia14'!$AC$28 -> 0 | Q8: ='Dia15'!$AC$28 -> 0 | R8: ='Dia16'!$AC$28 -> 0 | S8: ='Dia17'!$AC$28 -> 0 | T8: ='Dia18'!$AC$28 -> 0 | U8: ='Dia19'!$AC$28 -> 0 | V8: ='Dia20'!$AC$28 -> 0 | W8: =SUM(Tabla1[[#This Row],[05-mar]:[10-jul20]]) -> 1.1 | Z8: EL DE LOS BOLOS | AA8: 36.8 | AB8: 26.7 | AC8: 63.7 | AD8: 130.9 | AF8: 1 | AG8: =Partici!B39 -> 0 | AH8: =VLOOKUP(AG8,'DIA 1'!#REF!,2,0) -> #REF! | AK8: 1 | AL8: =Partici!C44 -> 0 | AM8: =VLOOKUP(AL8,'DIA 2'!$B$59:$C$126,2,0) -> 0 | AP8: 1 | AQ8: =Partici!D41 -> 0 | AR8: =VLOOKUP(AQ8,'DIA 3'!$B$59:$C$126,2,0) -> 0 | AU8: 1 | AV8: =Partici!E41 -> 0 | AW8: =VLOOKUP(AV8,'DIA 4'!$B$59:$C$126,2,0) -> 0 | AZ8: 1 | BA8: =Partici!F47 -> 0 | BB8: =VLOOKUP(BA8,'DIA 5'!$B$59:$C$126,2,0) -> 0 | BE8: 1 | BF8: =Partici!G47 -> 0 | BG8: =VLOOKUP(BF8,'DIA 6'!$B$59:$C$126,2,0) -> 0 | BJ8: 1 | BK8: =Partici!H47 -> 0 | BL8: =VLOOKUP(BK8,'DIA 7'!$B$59:$C$126,2,0) -> 0 | BO8: 1 | BP8: =Partici!I47 -> 0 | BQ8: =VLOOKUP(BP8,'DIA 8'!$B$59:$C$126,2,0) -> 0 | BR8: =$BQ$8-BQ8 -> 0 | BT8: 1 | BU8: =Partici!J47 -> 0 | BV8: =VLOOKUP(BU8,'DIA 9'!$B$59:$C$126,2,0) -> 0 | BY8: 1 | BZ8: =Partici!K47 -> 0 | CA8: =VLOOKUP(BZ8,'DIA 10'!$B$59:$C$126,2,0) -> 0 | CD8: 1 | CE8: =Partici!L47 -> 0 | CF8: =VLOOKUP(CE8,'DIA 11'!$B$59:$C$126,2,0) -> 0 | CI8: 1 | CJ8: =Partici!M47 -> 0 | CK8: =VLOOKUP(CJ8,'DIA 12'!$B$59:$C$126,2,0) -> 0 | CN8: 1 | CO8: =Partici!N47 -> 0 | CP8: =VLOOKUP(CO8,'24 12 23. CLUB'!$B$59:$C$126,2,0) -> 0
A9: 2 | B9: =+Partici!B16 -> SEA COURT 2 | C9: ='DIA 1'!$AC$35 -> 9.7 | D9: ='DIA 2'!$AC$35 -> 0 | E9: ='DIA 3'!$AC$35 -> 0 | F9: ='DIA 4'!$AC$35 -> 0 | G9: ='DIA 5'!$AC$35 -> 0 | H9: ='DIA 6'!$AC$35 -> 0 | I9: ='DIA 7'!$AC$35 -> 0 | J9: ='DIA 8'!$AC$35 -> 0 | K9: ='DIA 9'!$AC$35 -> 0 | L9: ='DIA 10'!$AC$35 -> 0 | M9: ='DIA 11'!$AC$35 -> 0 | N9: ='DIA 12'!$AC$35 -> 0 | O9: ='24 12 23. CLUB'!$AC$35 -> 0 | P9: ='Dia14'!$AC$30 -> 0 | Q9: ='Dia15'!$AC$30 -> 0 | R9: ='Dia16'!$AC$30 -> 0 | S9: ='Dia17'!$AC$30 -> 0 | T9: ='Dia18'!$AC$30 -> 0 | U9: ='Dia19'!$AC$30 -> 0 | V9: ='Dia20'!$AC$30 -> 0 | W9: =SUM(Tabla1[[#This Row],[05-mar]:[10-jul20]]) -> 9.7 | X9: =$W$8-Tabla1[[#This Row],[TOTAL]] -> -8.6 | Z9: SAN EUGENIO | AA9: 49 | AB9: 59.2 | AC9: 58 | AD9: 68.1 | AF9: 2 | AG9: =Partici!B46 -> 0 | AH9: =VLOOKUP(AG9,'DIA 1'!#REF!,2,0) -> #REF! | AI9: =$AH$8-AH9 -> #REF! | AK9: 2 | AL9: =Partici!C37 -> 0 | AM9: =VLOOKUP(AL9,'DIA 2'!$B$59:$C$126,2,0) -> 0 | AN9: =$AM$8-AM9 -> 0 | AP9: 2 | AQ9: =Partici!D35 -> 0 | AR9: =VLOOKUP(AQ9,'DIA 3'!$B$59:$C$126,2,0) -> 0 | AS9: =$AR$8-AR9 -> 0 | AU9: 2 | AV9: =Partici!E38 -> 0 | AW9: =VLOOKUP(AV9,'DIA 4'!$B$59:$C$126,2,0) -> 0 | AX9: =$AW$8-AW9 -> 0 | AZ9: 2 | BA9: =Partici!F36 -> 0 | BB9: =VLOOKUP(BA9,'DIA 5'!$B$59:$C$126,2,0) -> 0 | BC9: =$BB$8-BB9 -> 0 | BE9: 2 | BF9: =Partici!G36 -> 0 | BG9: =VLOOKUP(BF9,'DIA 6'!$B$59:$C$126,2,0) -> 0 | BH9: =$BG$8-BG9 -> 0 | BJ9: 2 | BK9: =Partici!H36 -> 0 | BL9: =VLOOKUP(BK9,'DIA 7'!$B$59:$C$126,2,0) -> 0 | BM9: =$BL$8-BL9 -> 0 | BO9: 2 | BP9: =Partici!I36 -> 0 | BQ9: =VLOOKUP(BP9,'DIA 8'!$B$59:$C$126,2,0) -> 0 | BR9: =$BQ$8-BQ9 -> 0 | BT9: 2 | BU9: =Partici!J36 -> 0 | BV9: =VLOOKUP(BU9,'DIA 9'!$B$59:$C$126,2,0) -> 0 | BW9: =$BV$8-BV9 -> 0 | BY9: 2 | BZ9: =Partici!K36 -> 0 | CA9: =VLOOKUP(BZ9,'DIA 10'!$B$59:$C$126,2,0) -> 0 | CB9: =$CA$8-CA9 -> 0 | CD9: 2 | CE9: =Partici!L36 -> 0 | CF9: =VLOOKUP(CE9,'DIA 11'!$B$59:$C$126,2,0) -> 0 | CG9: =$CF$8-CF9 -> 0 | CI9: 2 | CJ9: =Partici!M36 -> 0 | CK9: =VLOOKUP(CJ9,'DIA 12'!$B$59:$C$126,2,0) -> 0 | CL9: =$CK$8-CK9 -> 0 | CN9: 2 | CO9: =Partici!N36 -> 0 | CP9: =VLOOKUP(CO9,'24 12 23. CLUB'!$B$59:$C$126,2,0) -> 0 | CQ9: =$CP$8-CP9 -> 0
A10: 3 | B10: =+Partici!B14 -> TRES COPAS | C10: ='DIA 1'!$AC$31 -> 1.1 | D10: ='DIA 2'!$AC$31 -> 0 | E10: ='DIA 3'!$AC$31 -> 0 | F10: ='DIA 4'!$AC$31 -> 0 | G10: ='DIA 5'!$AC$31 -> 0 | H10: ='DIA 6'!$AC$31 -> 0 | I10: ='DIA 7'!$AC$31 -> 0 | J10: ='DIA 8'!$AC$31 -> 0 | K10: ='DIA 9'!$AC$31 -> 0 | L10: ='DIA 10'!$AC$31 -> 0 | M10: ='DIA 11'!$AC$31 -> 0 | N10: ='DIA 12'!$AC$31 -> 0 | O10: ='24 12 23. CLUB'!$AC$31 -> 0 | P10: ='Dia14'!$AC$26 -> 0 | Q10: ='Dia15'!$AC$26 -> 0 | R10: ='Dia16'!$AC$26 -> 0 | S10: ='Dia17'!$AC$26 -> 0 | T10: ='Dia18'!$AC$26 -> 0 | U10: ='Dia19'!$AC$26 -> 0 | V10: ='Dia20'!$AC$26 -> 0 | W10: =SUM(Tabla1[[#This Row],[05-mar]:[10-jul20]]) -> 1.1 | X10: =$W$8-Tabla1[[#This Row],[TOTAL]] -> 0 | Z10: CASTAÑO | AA10: 24.1 | AB10: 60 | AC10: 51.7 | AD10: 71.5 | AF10: 3 | AG10: =Partici!B43 -> 0 | AH10: =VLOOKUP(AG10,'DIA 1'!#REF!,2,0) -> #REF! | AI10: =$AH$8-AH10 -> #REF! | AK10: 3 | AL10: =Partici!C41 -> 0 | AM10: =VLOOKUP(AL10,'DIA 2'!$B$59:$C$126,2,0) -> 0 | AN10: =$AM$8-AM10 -> 0 | AP10: 3 | AQ10: =Partici!D39 -> 0 | AR10: =VLOOKUP(AQ10,'DIA 3'!$B$59:$C$126,2,0) -> 0 | AS10: =$AR$8-AR10 -> 0 | AU10: 3 | AV10: =Partici!E37 -> 0 | AW10: =VLOOKUP(AV10,'DIA 4'!$B$59:$C$126,2,0) -> 0 | AX10: =$AW$8-AW10 -> 0 | AZ10: 3 | BA10: =Partici!F43 -> 0 | BB10: =VLOOKUP(BA10,'DIA 5'!$B$59:$C$126,2,0) -> 0 | BC10: =$BB$8-BB10 -> 0 | BE10: 3 | BF10: =Partici!G43 -> 0 | BG10: =VLOOKUP(BF10,'DIA 6'!$B$59:$C$126,2,0) -> 0 | BH10: =$BG$8-BG10 -> 0 | BJ10: 3 | BK10: =Partici!H43 -> 0 | BL10: =VLOOKUP(BK10,'DIA 7'!$B$59:$C$126,2,0) -> 0 | BM10: =$BL$8-BL10 -> 0 | BO10: 3 | BP10: =Partici!I43 -> 0 | BQ10: =VLOOKUP(BP10,'DIA 8'!$B$59:$C$126,2,0) -> 0 | BR10: =$BQ$8-BQ10 -> 0 | BT10: 3 | BU10: =Partici!J43 -> 0 | BV10: =VLOOKUP(BU10,'DIA 9'!$B$59:$C$126,2,0) -> 0 | BW10: =$BV$8-BV10 -> 0 | BY10: 3 | BZ10: =Partici!K43 -> 0 | CA10: =VLOOKUP(BZ10,'DIA 10'!$B$59:$C$126,2,0) -> 0 | CB10: =$CA$8-CA10 -> 0 | CD10: 3 | CE10: =Partici!L43 -> 0 | CF10: =VLOOKUP(CE10,'DIA 11'!$B$59:$C$126,2,0) -> 0 | CG10: =$CF$8-CF10 -> 0 | CI10: 3 | CJ10: =Partici!M43 -> 0 | CK10: =VLOOKUP(CJ10,'DIA 12'!$B$59:$C$126,2,0) -> 0 | CL10: =$CK$8-CK10 -> 0 | CN10: 3 | CO10: =Partici!N43 -> 0 | CP10: =VLOOKUP(CO10,'24 12 23. CLUB'!$B$59:$C$126,2,0) -> 0 | CQ10: =$CP$8-CP10 -> 0
A11: 4 | B11: =+Partici!B6 -> SALVAYORK | C11: ='DIA 1'!$AC$15 -> 9.7 | D11: ='DIA 2'!$AC$15 -> 0 | E11: ='DIA 3'!$AC$15 -> 0 | F11: ='DIA 4'!$AC$15 -> 0 | G11: ='DIA 5'!$AC$15 -> 0 | H11: ='DIA 6'!$AC$15 -> 0 | I11: ='DIA 7'!$AC$15 -> 0 | J11: ='DIA 8'!$AC$15 -> 0 | K11: ='DIA 9'!$AC$15 -> 0 | L11: ='DIA 10'!$AC$15 -> 0 | M11: ='DIA 11'!$AC$15 -> 0 | N11: ='DIA 12'!$AC$15 -> 0 | O11: ='24 12 23. CLUB'!$AC$15 -> 0 | P11: ='Dia14'!$AC$10 -> 0 | Q11: ='Dia15'!$AC$10 -> 0 | R11: ='Dia16'!$AC$10 -> 0 | S11: ='Dia17'!$AC$10 -> 0 | T11: ='Dia18'!$AC$10 -> 0 | U11: ='Dia19'!$AC$10 -> 0 | V11: ='Dia20'!$AC$10 -> 0 | W11: =SUM(Tabla1[[#This Row],[05-mar]:[10-jul20]]) -> 9.7 | X11: =$W$8-Tabla1[[#This Row],[TOTAL]] -> -8.6 | Z11: NANO | AA11: 67.2 | AB11: 42.5 | AC11: 67.3 | AD11: 27.8 | AF11: 4 | AG11: =Partici!B36 -> 0 | AH11: =VLOOKUP(AG11,'DIA 1'!#REF!,2,0) -> #REF! | AI11: =$AH$8-AH11 -> #REF! | AK11: 4 | AL11: =Partici!C45 -> 0 | AM11: =VLOOKUP(AL11,'DIA 2'!$B$59:$C$126,2,0) -> 0 | AN11: =$AM$8-AM11 -> 0 | AP11: 4 | AQ11: =Partici!D42 -> 0 | AR11: =VLOOKUP(AQ11,'DIA 3'!$B$59:$C$126,2,0) -> 0 | AS11: =$AR$8-AR11 -> 0 | AU11: 4 | AV11: =Partici!E42 -> 0 | AW11: =VLOOKUP(AV11,'DIA 4'!$B$59:$C$126,2,0) -> 0 | AX11: =$AW$8-AW11 -> 0 | AZ11: 4 | BA11: =Partici!F45 -> 0 | BB11: =VLOOKUP(BA11,'DIA 5'!$B$59:$C$126,2,0) -> 0 | BC11: =$BB$8-BB11 -> 0 | BE11: 4 | BF11: =Partici!G45 -> 0 | BG11: =VLOOKUP(BF11,'DIA 6'!$B$59:$C$126,2,0) -> 0 | BH11: =$BG$8-BG11 -> 0 | BJ11: 4 | BK11: =Partici!H45 -> 0 | BL11: =VLOOKUP(BK11,'DIA 7'!$B$59:$C$126,2,0) -> 0 | BM11: =$BL$8-BL11 -> 0 | BO11: 4 | BP11: =Partici!I45 -> 0 | BQ11: =VLOOKUP(BP11,'DIA 8'!$B$59:$C$126,2,0) -> 0 | BR11: =$BQ$8-BQ11 -> 0 | BT11: 4 | BU11: =Partici!J45 -> 0 | BV11: =VLOOKUP(BU11,'DIA 9'!$B$59:$C$126,2,0) -> 0 | BW11: =$BV$8-BV11 -> 0 | BY11: 4 | BZ11: =Partici!K45 -> 0 | CA11: =VLOOKUP(BZ11,'DIA 10'!$B$59:$C$126,2,0) -> 0 | CB11: =$CA$8-CA11 -> 0 | CD11: 4 | CE11: =Partici!L45 -> 0 | CF11: =VLOOKUP(CE11,'DIA 11'!$B$59:$C$126,2,0) -> 0 | CG11: =$CF$8-CF11 -> 0 | CI11: 4 | CJ11: =Partici!M45 -> 0 | CK11: =VLOOKUP(CJ11,'DIA 12'!$B$59:$C$126,2,0) -> 0 | CL11: =$CK$8-CK11 -> 0 | CN11: 4 | CO11: =Partici!N45 -> 0 | CP11: =VLOOKUP(CO11,'24 12 23. CLUB'!$B$59:$C$126,2,0) -> 0 | CQ11: =$CP$8-CP11 -> 0
A12: 5 | B12: =+Partici!B17 -> MANZOR | C12: ='DIA 1'!$AC$37 -> 1.1 | D12: ='DIA 2'!$AC$37 -> 0 | E12: ='DIA 3'!$AC$37 -> 0 | F12: ='DIA 4'!$AC$37 -> 0 | G12: ='DIA 5'!$AC$37 -> 0 | H12: ='DIA 6'!$AC$37 -> 0 | I12: ='DIA 7'!$AC$37 -> 0 | J12: ='DIA 8'!$AC$37 -> 0 | K12: ='DIA 9'!$AC$37 -> 0 | L12: ='DIA 10'!$AC$37 -> 0 | M12: ='DIA 11'!$AC$37 -> 0 | N12: ='DIA 12'!$AC$37 -> 0 | O12: ='24 12 23. CLUB'!$AC$37 -> 0 | P12: ='Dia14'!$AC$32 -> 0 | Q12: ='Dia15'!$AC$32 -> 0 | R12: ='Dia16'!$AC$32 -> 0 | S12: ='Dia17'!$AC$32 -> 0 | T12: ='Dia18'!$AC$32 -> 0 | U12: ='Dia19'!$AC$32 -> 0 | V12: ='Dia20'!$AC$32 -> 0 | W12: =SUM(Tabla1[[#This Row],[05-mar]:[10-jul20]]) -> 1.1 | X12: =$W$8-Tabla1[[#This Row],[TOTAL]] -> 0 | Z12: FERNANDA | AA12: 37.7 | AB12: 28.9 | AC12: 41.3 | AD12: 89.9 | AF12: 5 | AG12: =Partici!B41 -> 0 | AH12: =VLOOKUP(AG12,'DIA 1'!#REF!,2,0) -> #REF! | AI12: =$AH$8-AH12 -> #REF! | AK12: 5 | AL12: =Partici!C46 -> 0 | AM12: =VLOOKUP(AL12,'DIA 2'!$B$59:$C$126,2,0) -> 0 | AN12: =$AM$8-AM12 -> 0 | AP12: 5 | AQ12: =Partici!D45 -> 0 | AR12: =VLOOKUP(AQ12,'DIA 3'!$B$59:$C$126,2,0) -> 0 | AS12: =$AR$8-AR12 -> 0 | AU12: 5 | AV12: =Partici!E46 -> 0 | AW12: =VLOOKUP(AV12,'DIA 4'!$B$59:$C$126,2,0) -> 0 | AX12: =$AW$8-AW12 -> 0 | AZ12: 5 | BA12: =Partici!F38 -> 0 | BB12: =VLOOKUP(BA12,'DIA 5'!$B$59:$C$126,2,0) -> 0 | BC12: =$BB$8-BB12 -> 0 | BE12: 5 | BF12: =Partici!G38 -> 0 | BG12: =VLOOKUP(BF12,'DIA 6'!$B$59:$C$126,2,0) -> 0 | BH12: =$BG$8-BG12 -> 0 | BJ12: 5 | BK12: =Partici!H38 -> 0 | BL12: =VLOOKUP(BK12,'DIA 7'!$B$59:$C$126,2,0) -> 0 | BM12: =$BL$8-BL12 -> 0 | BO12: 5 | BP12: =Partici!I38 -> 0 | BQ12: =VLOOKUP(BP12,'DIA 8'!$B$59:$C$126,2,0) -> 0 | BR12: =$BQ$8-BQ12 -> 0 | BT12: 5 | BU12: =Partici!J38 -> 0 | BV12: =VLOOKUP(BU12,'DIA 9'!$B$59:$C$126,2,0) -> 0 | BW12: =$BV$8-BV12 -> 0 | BY12: 5 | BZ12: =Partici!K38 -> 0 | CA12: =VLOOKUP(BZ12,'DIA 10'!$B$59:$C$126,2,0) -> 0 | CB12: =$CA$8-CA12 -> 0 | CD12: 5 | CE12: =Partici!L38 -> 0 | CF12: =VLOOKUP(CE12,'DIA 11'!$B$59:$C$126,2,0) -> 0 | CG12: =$CF$8-CF12 -> 0 | CI12: 5 | CJ12: =Partici!M38 -> 0 | CK12: =VLOOKUP(CJ12,'DIA 12'!$B$59:$C$126,2,0) -> 0 | CL12: =$CK$8-CK12 -> 0 | CN12: 5 | CO12: =Partici!N38 -> 0 | CP12: =VLOOKUP(CO12,'24 12 23. CLUB'!$B$59:$C$126,2,0) -> 0 | CQ12: =$CP$8-CP12 -> 0
A13: 6 | B13: =+Partici!B18 -> ARRE DEMONIO | C13: ='DIA 1'!$AC$39 -> 0 | D13: ='DIA 2'!$AC$39 -> 0 | E13: ='DIA 3'!$AC$39 -> 0 | F13: ='DIA 4'!$AC$39 -> 0 | G13: ='DIA 5'!$AC$39 -> 0 | H13: ='DIA 6'!$AC$39 -> 0 | I13: ='DIA 7'!$AC$39 -> 0 | J13: ='DIA 8'!$AC$39 -> 0 | K13: ='DIA 9'!$AC$39 -> 0 | L13: ='DIA 10'!$AC$39 -> 0 | M13: ='DIA 11'!$AC$39 -> 0 | N13: ='DIA 12'!$AC$39 -> 0 | O13: ='24 12 23. CLUB'!$AC$39 -> 0 | P13: ='Dia14'!$AC$34 -> 0 | Q13: ='Dia15'!$AC$34 -> 0 | R13: ='Dia16'!$AC$34 -> 0 | S13: ='Dia17'!$AC$34 -> 0 | T13: ='Dia18'!$AC$34 -> 0 | U13: ='Dia19'!$AC$34 -> 0 | V13: ='Dia20'!$AC$34 -> 0 | W13: =SUM(Tabla1[[#This Row],[05-mar]:[10-jul20]]) -> 0 | X13: =$W$8-Tabla1[[#This Row],[TOTAL]] -> 1.1 | Z13: SERVIFRENOS | AA13: 44.2 | AB13: 55.1 | AC13: 49.2 | AD13: 48.7 | AF13: 6 | AG13: =Partici!B38 -> 0 | AH13: =VLOOKUP(AG13,'DIA 1'!#REF!,2,0) -> #REF! | AI13: =$AH$8-AH13 -> #REF! | AK13: 6 | AL13: =Partici!C36 -> 0 | AM13: =VLOOKUP(AL13,'DIA 2'!$B$59:$C$126,2,0) -> 0 | AN13: =$AM$8-AM13 -> 0 | AP13: 6 | AQ13: =Partici!D48 -> 0 | AR13: =VLOOKUP(AQ13,'DIA 3'!$B$59:$C$126,2,0) -> 0 | AS13: =$AR$8-AR13 -> 0 | AU13: 6 | AV13: =Partici!E45 -> 0 | AW13: =VLOOKUP(AV13,'DIA 4'!$B$59:$C$126,2,0) -> 0 | AX13: =$AW$8-AW13 -> 0 | AZ13: 6 | BA13: =Partici!F55 -> 0 | BB13: =VLOOKUP(BA13,'DIA 5'!$B$59:$C$126,2,0) -> 0 | BC13: =$BB$8-BB13 -> 0 | BE13: 6 | BF13: =Partici!G55 -> 0 | BG13: =VLOOKUP(BF13,'DIA 6'!$B$59:$C$126,2,0) -> 0 | BH13: =$BG$8-BG13 -> 0 | BJ13: 6 | BK13: =Partici!H55 -> 0 | BL13: =VLOOKUP(BK13,'DIA 7'!$B$59:$C$126,2,0) -> 0 | BM13: =$BL$8-BL13 -> 0 | BO13: 6 | BP13: =Partici!I55 -> 0 | BQ13: =VLOOKUP(BP13,'DIA 8'!$B$59:$C$126,2,0) -> 0 | BR13: =$BQ$8-BQ13 -> 0 | BT13: 6 | BU13: =Partici!J55 -> 0 | BV13: =VLOOKUP(BU13,'DIA 9'!$B$59:$C$126,2,0) -> 0 | BW13: =$BV$8-BV13 -> 0 | BY13: 6 | BZ13: =Partici!K55 -> 0 | CA13: =VLOOKUP(BZ13,'DIA 10'!$B$59:$C$126,2,0) -> 0 | CB13: =$CA$8-CA13 -> 0 | CD13: 6 | CE13: =Partici!L55 -> 0 | CF13: =VLOOKUP(CE13,'DIA 11'!$B$59:$C$126,2,0) -> 0 | CG13: =$CF$8-CF13 -> 0 | CI13: 6 | CJ13: =Partici!M55 -> 0 | CK13: =VLOOKUP(CJ13,'DIA 12'!$B$59:$C$126,2,0) -> 0 | CL13: =$CK$8-CK13 -> 0 | CN13: 6 | CO13: =Partici!N55 -> 0 | CP13: =VLOOKUP(CO13,'24 12 23. CLUB'!$B$59:$C$126,2,0) -> 0 | CQ13: =$CP$8-CP13 -> 0
A14: 7 | B14: =+Partici!B9 -> AUMENTA MEDINA | C14: ='DIA 1'!$AC$21 -> 1.1 | D14: ='DIA 2'!$AC$21 -> 0 | E14: ='DIA 3'!$AC$21 -> 0 | F14: ='DIA 4'!$AC$21 -> 0 | G14: ='DIA 5'!$AC$21 -> 0 | H14: ='DIA 6'!$AC$21 -> 0 | I14: ='DIA 7'!$AC$21 -> 0 | J14: ='DIA 8'!$AC$21 -> 0 | K14: ='DIA 9'!$AC$21 -> 0 | L14: ='DIA 10'!$AC$21 -> 0 | M14: ='DIA 11'!$AC$21 -> 0 | N14: ='DIA 12'!$AC$21 -> 0 | O14: ='24 12 23. CLUB'!$AC$21 -> 0 | P14: ='Dia14'!$AC$16 -> 0 | Q14: ='Dia15'!$AC$16 -> 0 | R14: ='Dia16'!$AC$16 -> 0 | S14: ='Dia17'!$AC$16 -> 0 | T14: ='Dia18'!$AC$16 -> 0 | U14: ='Dia19'!$AC$16 -> 0 | V14: ='Dia20'!$AC$16 -> 0 | W14: =SUM(Tabla1[[#This Row],[05-mar]:[10-jul20]]) -> 1.1 | X14: =$W$8-Tabla1[[#This Row],[TOTAL]] -> 0 | Z14: KOKE | AA14: 48.6 | AB14: 54.9 | AC14: 50.1 | AD14: 41.8 | AF14: 7 | AG14: =Partici!B37 -> 0 | AH14: =VLOOKUP(AG14,'DIA 1'!#REF!,2,0) -> #REF! | AI14: =$AH$8-AH14 -> #REF! | AK14: 7 | AL14: =Partici!C39 -> 0 | AM14: =VLOOKUP(AL14,'DIA 2'!$B$59:$C$126,2,0) -> 0 | AN14: =$AM$8-AM14 -> 0 | AP14: 7 | AQ14: =Partici!D46 -> 0 | AR14: =VLOOKUP(AQ14,'DIA 3'!$B$59:$C$126,2,0) -> 0 | AS14: =$AR$8-AR14 -> 0 | AU14: 7 | AV14: =Partici!E47 -> 0 | AW14: =VLOOKUP(AV14,'DIA 4'!$B$59:$C$126,2,0) -> 0 | AX14: =$AW$8-AW14 -> 0 | AZ14: 7 | BA14: =Partici!F50 -> 0 | BB14: =VLOOKUP(BA14,'DIA 5'!$B$59:$C$126,2,0) -> 0 | BC14: =$BB$8-BB14 -> 0 | BE14: 7 | BF14: =Partici!G50 -> 0 | BG14: =VLOOKUP(BF14,'DIA 6'!$B$59:$C$126,2,0) -> 0 | BH14: =$BG$8-BG14 -> 0 | BJ14: 7 | BK14: =Partici!H50 -> 0 | BL14: =VLOOKUP(BK14,'DIA 7'!$B$59:$C$126,2,0) -> 0 | BM14: =$BL$8-BL14 -> 0 | BO14: 7 | BP14: =Partici!I50 -> 0 | BQ14: =VLOOKUP(BP14,'DIA 8'!$B$59:$C$126,2,0) -> 0 | BR14: =$BQ$8-BQ14 -> 0 | BT14: 7 | BU14: =Partici!J50 -> 0 | BV14: =VLOOKUP(BU14,'DIA 9'!$B$59:$C$126,2,0) -> 0 | BW14: =$BV$8-BV14 -> 0 | BY14: 7 | BZ14: =Partici!K50 -> 0 | CA14: =VLOOKUP(BZ14,'DIA 10'!$B$59:$C$126,2,0) -> 0 | CB14: =$CA$8-CA14 -> 0 | CD14: 7 | CE14: =Partici!L50 -> 0 | CF14: =VLOOKUP(CE14,'DIA 11'!$B$59:$C$126,2,0) -> 0 | CG14: =$CF$8-CF14 -> 0 | CI14: 7 | CJ14: =Partici!M50 -> 0 | CK14: =VLOOKUP(CJ14,'DIA 12'!$B$59:$C$126,2,0) -> 0 | CL14: =$CK$8-CK14 -> 0 | CN14: 7 | CO14: =Partici!N50 -> 0 | CP14: =VLOOKUP(CO14,'24 12 23. CLUB'!$B$59:$C$126,2,0) -> 0 | CQ14: =$CP$8-CP14 -> 0
A15: 8 | B15: =+Partici!B19 -> SOSAMAFIA | C15: ='DIA 1'!$AC$41 -> 0 | D15: ='DIA 2'!$AC$41 -> 0 | E15: ='DIA 3'!$AC$41 -> 0 | F15: ='DIA 4'!$AC$41 -> 0 | G15: ='DIA 5'!$AC$41 -> 0 | H15: ='DIA 6'!$AC$41 -> 0 | I15: ='DIA 7'!$AC$41 -> 0 | J15: ='DIA 8'!$AC$41 -> 0 | K15: ='DIA 9'!$AC$41 -> 0 | L15: ='DIA 10'!$AC$41 -> 0 | M15: ='DIA 11'!$AC$41 -> 0 | N15: ='DIA 12'!$AC$41 -> 0 | O15: ='24 12 23. CLUB'!$AC$41 -> 0 | P15: ='Dia14'!$AC$36 -> 0 | Q15: ='Dia15'!$AC$36 -> 0 | R15: ='Dia16'!$AC$36 -> 0 | S15: ='Dia17'!$AC$36 -> 0 | T15: ='Dia18'!$AC$36 -> 0 | U15: ='Dia19'!$AC$36 -> 0 | V15: ='Dia20'!$AC$36 -> 0 | W15: =SUM(Tabla1[[#This Row],[05-mar]:[10-jul20]]) -> 0 | X15: =$W$8-Tabla1[[#This Row],[TOTAL]] -> 1.1 | Z15: AUMENTA MEDINA | AA15: 74.1 | AB15: 26.1 | AC15: 43.7 | AD15: 46 | AF15: 8 | AG15: =Partici!B35 -> 0 | AH15: =VLOOKUP(AG15,'DIA 1'!#REF!,2,0) -> #REF! | AI15: =$AH$8-AH15 -> #REF! | AK15: 8 | AL15: =Partici!C35 -> 0 | AM15: =VLOOKUP(AL15,'DIA 2'!$B$59:$C$126,2,0) -> 0 | AN15: =$AM$8-AM15 -> 0 | AP15: 8 | AQ15: =Partici!D49 -> 0 | AR15: =VLOOKUP(AQ15,'DIA 3'!$B$59:$C$126,2,0) -> 0 | AS15: =$AR$8-AR15 -> 0 | AU15: 8 | AV15: =Partici!E44 -> 0 | AW15: =VLOOKUP(AV15,'DIA 4'!$B$59:$C$126,2,0) -> 0 | AX15: =$AW$8-AW15 -> 0 | AZ15: 8 | BA15: =Partici!F44 -> 0 | BB15: =VLOOKUP(BA15,'DIA 5'!$B$59:$C$126,2,0) -> 0 | BC15: =$BB$8-BB15 -> 0 | BE15: 8 | BF15: =Partici!G44 -> 0 | BG15: =VLOOKUP(BF15,'DIA 6'!$B$59:$C$126,2,0) -> 0 | BH15: =$BG$8-BG15 -> 0 | BJ15: 8 | BK15: =Partici!H44 -> 0 | BL15: =VLOOKUP(BK15,'DIA 7'!$B$59:$C$126,2,0) -> 0 | BM15: =$BL$8-BL15 -> 0 | BO15: 8 | BP15: =Partici!I44 -> 0 | BQ15: =VLOOKUP(BP15,'DIA 8'!$B$59:$C$126,2,0) -> 0 | BR15: =$BQ$8-BQ15 -> 0 | BT15: 8 | BU15: =Partici!J44 -> 0 | BV15: =VLOOKUP(BU15,'DIA 9'!$B$59:$C$126,2,0) -> 0 | BW15: =$BV$8-BV15 -> 0 | BY15: 8 | BZ15: =Partici!K44 -> 0 | CA15: =VLOOKUP(BZ15,'DIA 10'!$B$59:$C$126,2,0) -> 0 | CB15: =$CA$8-CA15 -> 0 | CD15: 8 | CE15: =Partici!L44 -> 0 | CF15: =VLOOKUP(CE15,'DIA 11'!$B$59:$C$126,2,0) -> 0 | CG15: =$CF$8-CF15 -> 0 | CI15: 8 | CJ15: =Partici!M44 -> 0 | CK15: =VLOOKUP(CJ15,'DIA 12'!$B$59:$C$126,2,0) -> 0 | CL15: =$CK$8-CK15 -> 0 | CN15: 8 | CO15: =Partici!N44 -> 0 | CP15: =VLOOKUP(CO15,'24 12 23. CLUB'!$B$59:$C$126,2,0) -> 0 | CQ15: =$CP$8-CP15 -> 0
A16: 9 | B16: =+Partici!B12 -> SERVIFRENOS | C16: ='DIA 1'!$AC$27 -> 0 | D16: ='DIA 2'!$AC$27 -> 0 | E16: ='DIA 3'!$AC$27 -> 0 | F16: ='DIA 4'!$AC$27 -> 0 | G16: ='DIA 5'!$AC$27 -> 0 | H16: ='DIA 6'!$AC$27 -> 0 | I16: ='DIA 7'!$AC$27 -> 0 | J16: ='DIA 8'!$AC$27 -> 0 | K16: ='DIA 9'!$AC$27 -> 0 | L16: ='DIA 10'!$AC$27 -> 0 | M16: ='DIA 11'!$AC$27 -> 0 | N16: ='DIA 12'!$AC$27 -> 0 | O16: ='24 12 23. CLUB'!$AC$27 -> 0 | P16: ='Dia14'!$AC$22 -> 0 | Q16: ='Dia15'!$AC$22 -> 0 | R16: ='Dia16'!$AC$22 -> 0 | S16: ='Dia17'!$AC$22 -> 0 | T16: ='Dia18'!$AC$22 -> 0 | U16: ='Dia19'!$AC$22 -> 0 | V16: ='Dia20'!$AC$22 -> 0 | W16: =SUM(Tabla1[[#This Row],[05-mar]:[10-jul20]]) -> 0 | X16: =$W$8-Tabla1[[#This Row],[TOTAL]] -> 1.1 | Z16: COSMITO | AA16: 18.5 | AB16: 67 | AC16: 68.4 | AD16: 26.9 | AF16: 9 | AG16: =Partici!B42 -> 0 | AH16: =VLOOKUP(AG16,'DIA 1'!#REF!,2,0) -> #REF! | AI16: =$AH$8-AH16 -> #REF! | AK16: 9 | AL16: =Partici!C43 -> 0 | AM16: =VLOOKUP(AL16,'DIA 2'!$B$59:$C$126,2,0) -> 0 | AN16: =$AM$8-AM16 -> 0 | AP16: 9 | AQ16: =Partici!D40 -> 0 | AR16: =VLOOKUP(AQ16,'DIA 3'!$B$59:$C$126,2,0) -> 0 | AS16: =$AR$8-AR16 -> 0 | AU16: 9 | AV16: =Partici!E43 -> 0 | AW16: =VLOOKUP(AV16,'DIA 4'!$B$59:$C$126,2,0) -> 0 | AX16: =$AW$8-AW16 -> 0 | AZ16: 9 | BA16: =Partici!F40 -> 0 | BB16: =VLOOKUP(BA16,'DIA 5'!$B$59:$C$126,2,0) -> 0 | BC16: =$BB$8-BB16 -> 0 | BE16: 9 | BF16: =Partici!G40 -> 0 | BG16: =VLOOKUP(BF16,'DIA 6'!$B$59:$C$126,2,0) -> 0 | BH16: =$BG$8-BG16 -> 0 | BJ16: 9 | BK16: =Partici!H40 -> 0 | BL16: =VLOOKUP(BK16,'DIA 7'!$B$59:$C$126,2,0) -> 0 | BM16: =$BL$8-BL16 -> 0 | BO16: 9 | BP16: =Partici!I40 -> 0 | BQ16: =VLOOKUP(BP16,'DIA 8'!$B$59:$C$126,2,0) -> 0 | BR16: =$BQ$8-BQ16 -> 0 | BT16: 9 | BU16: =Partici!J40 -> 0 | BV16: =VLOOKUP(BU16,'DIA 9'!$B$59:$C$126,2,0) -> 0 | BW16: =$BV$8-BV16 -> 0 | BY16: 9 | BZ16: =Partici!K40 -> 0 | CA16: =VLOOKUP(BZ16,'DIA 10'!$B$59:$C$126,2,0) -> 0 | CB16: =$CA$8-CA16 -> 0 | CD16: 9 | CE16: =Partici!L40 -> 0 | CF16: =VLOOKUP(CE16,'DIA 11'!$B$59:$C$126,2,0) -> 0 | CG16: =$CF$8-CF16 -> 0 | CI16: 9 | CJ16: =Partici!M40 -> 0 | CK16: =VLOOKUP(CJ16,'DIA 12'!$B$59:$C$126,2,0) -> 0 | CL16: =$CK$8-CK16 -> 0 | CN16: 9 | CO16: =Partici!N40 -> 0 | CP16: =VLOOKUP(CO16,'24 12 23. CLUB'!$B$59:$C$126,2,0) -> 0 | CQ16: =$CP$8-CP16 -> 0
A17: 10 | B17: =+Partici!B4 -> TRINIDAD | C17: ='DIA 1'!$AC$11 -> 0 | D17: ='DIA 2'!$AC$11 -> 0 | E17: ='DIA 3'!$AC$11 -> 0 | F17: ='DIA 4'!$AC$11 -> 0 | G17: ='DIA 5'!$AC$11 -> 0 | H17: ='DIA 6'!$AC$11 -> 0 | I17: ='DIA 7'!$AC$11 -> 0 | J17: ='DIA 8'!$AC$11 -> 0 | K17: ='DIA 9'!$AC$11 -> 0 | L17: ='DIA 10'!$AC$11 -> 0 | M17: ='DIA 11'!$AC$11 -> 0 | N17: ='DIA 12'!$AC$11 -> 0 | O17: ='24 12 23. CLUB'!$AC$11 -> 0 | P17: ='Dia14'!$AC$6 -> 0 | Q17: ='Dia15'!$AC$6 -> 0 | R17: ='Dia16'!$AC$6 -> 0 | S17: ='Dia17'!$AC$6 -> 0 | T17: ='Dia18'!$AC$6 -> 0 | U17: ='Dia19'!$AC$6 -> 0 | V17: ='Dia20'!$AC$6 -> 0 | W17: =SUM(Tabla1[[#This Row],[05-mar]:[10-jul20]]) -> 0 | X17: =$W$8-Tabla1[[#This Row],[TOTAL]] -> 1.1 | Z17: EL SIETE DE LA SUERTE | AA17: 40.8 | AB17: 43.5 | AC17: 61.1 | AD17: 35.4 | AF17: 10 | AG17: =Partici!B45 -> 0 | AH17: =VLOOKUP(AG17,'DIA 1'!#REF!,2,0) -> #REF! | AI17: =$AH$8-AH17 -> #REF! | AK17: 10 | AL17: =Partici!C42 -> 0 | AM17: =VLOOKUP(AL17,'DIA 2'!$B$59:$C$126,2,0) -> 0 | AN17: =$AM$8-AM17 -> 0 | AP17: 10 | AQ17: =Partici!D37 -> 0 | AR17: =VLOOKUP(AQ17,'DIA 3'!$B$59:$C$126,2,0) -> 0 | AS17: =$AR$8-AR17 -> 0 | AU17: 10 | AV17: =Partici!E39 -> 0 | AW17: =VLOOKUP(AV17,'DIA 4'!$B$59:$C$126,2,0) -> 0 | AX17: =$AW$8-AW17 -> 0 | AZ17: 10 | BA17: =Partici!F48 -> 0 | BB17: =VLOOKUP(BA17,'DIA 5'!$B$59:$C$126,2,0) -> 0 | BC17: =$BB$8-BB17 -> 0 | BE17: 10 | BF17: =Partici!G48 -> 0 | BG17: =VLOOKUP(BF17,'DIA 6'!$B$59:$C$126,2,0) -> 0 | BH17: =$BG$8-BG17 -> 0 | BJ17: 10 | BK17: =Partici!H48 -> 0 | BL17: =VLOOKUP(BK17,'DIA 7'!$B$59:$C$126,2,0) -> 0 | BM17: =$BL$8-BL17 -> 0 | BO17: 10 | BP17: =Partici!I48 -> 0 | BQ17: =VLOOKUP(BP17,'DIA 8'!$B$59:$C$126,2,0) -> 0 | BR17: =$BQ$8-BQ17 -> 0 | BT17: 10 | BU17: =Partici!J48 -> 0 | BV17: =VLOOKUP(BU17,'DIA 9'!$B$59:$C$126,2,0) -> 0 | BW17: =$BV$8-BV17 -> 0 | BY17: 10 | BZ17: =Partici!K48 -> 0 | CA17: =VLOOKUP(BZ17,'DIA 10'!$B$59:$C$126,2,0) -> 0 | CB17: =$CA$8-CA17 -> 0 | CD17: 10 | CE17: =Partici!L48 -> 0 | CF17: =VLOOKUP(CE17,'DIA 11'!$B$59:$C$126,2,0) -> 0 | CG17: =$CF$8-CF17 -> 0 | CI17: 10 | CJ17: =Partici!M48 -> 0 | CK17: =VLOOKUP(CJ17,'DIA 12'!$B$59:$C$126,2,0) -> 0 | CL17: =$CK$8-CK17 -> 0 | CN17: 10 | CO17: =Partici!N48 -> 0 | CP17: =VLOOKUP(CO17,'24 12 23. CLUB'!$B$59:$C$126,2,0) -> 0 | CQ17: =$CP$8-CP17 -> 0
A18: 11 | B18: =+Partici!B20 -> MIS SOBRINOS | C18: ='DIA 1'!$AC$43 -> 3.9 | D18: ='DIA 2'!$AC$43 -> 0 | E18: ='DIA 3'!$AC$43 -> 0 | F18: ='DIA 4'!$AC$43 -> 0 | G18: ='DIA 5'!$AC$43 -> 0 | H18: ='DIA 6'!$AC$43 -> 0 | I18: ='DIA 7'!$AC$43 -> 0 | J18: ='DIA 8'!$AC$43 -> 0 | K18: ='DIA 9'!$AC$43 -> 0 | L18: ='DIA 10'!$AC$43 -> 0 | M18: ='DIA 11'!$AC$43 -> 0 | N18: ='DIA 12'!$AC$43 -> 0 | O18: ='24 12 23. CLUB'!$AC$43 -> 0 | P18: ='Dia14'!$AC$38 -> 0 | Q18: ='Dia15'!$AC$38 -> 0 | R18: ='Dia16'!$AC$38 -> 0 | S18: ='Dia17'!$AC$38 -> 0 | T18: ='Dia18'!$AC$38 -> 0 | U18: ='Dia19'!$AC$38 -> 0 | V18: ='Dia20'!$AC$38 -> 0 | W18: =SUM(Tabla1[[#This Row],[05-mar]:[10-jul20]]) -> 3.9 | X18: =$W$8-Tabla1[[#This Row],[TOTAL]] -> -2.8 | Z18: VOLVIO MEDINA | AA18: 76.1 | AB18: 36.6 | AC18: 40.8 | AD18: 24.9 | AF18: 11 | AG18: =Partici!B40 -> 0 | AH18: =VLOOKUP(AG18,'DIA 1'!#REF!,2,0) -> #REF! | AI18: =$AH$8-AH18 -> #REF! | AK18: 11 | AL18: =Partici!C40 -> 0 | AM18: =VLOOKUP(AL18,'DIA 2'!$B$59:$C$126,2,0) -> 0 | AN18: =$AM$8-AM18 -> 0 | AP18: 11 | AQ18: =Partici!D44 -> 0 | AR18: =VLOOKUP(AQ18,'DIA 3'!$B$59:$C$126,2,0) -> 0 | AS18: =$AR$8-AR18 -> 0 | AU18: 11 | AV18: =Partici!E35 -> 0 | AW18: =VLOOKUP(AV18,'DIA 4'!$B$59:$C$126,2,0) -> 0 | AX18: =$AW$8-AW18 -> 0 | AZ18: 11 | BA18: =Partici!F51 -> 0 | BB18: =VLOOKUP(BA18,'DIA 5'!$B$59:$C$126,2,0) -> 0 | BC18: =$BB$8-BB18 -> 0 | BE18: 11 | BF18: =Partici!G51 -> 0 | BG18: =VLOOKUP(BF18,'DIA 6'!$B$59:$C$126,2,0) -> 0 | BH18: =$BG$8-BG18 -> 0 | BJ18: 11 | BK18: =Partici!H51 -> 0 | BL18: =VLOOKUP(BK18,'DIA 7'!$B$59:$C$126,2,0) -> 0 | BM18: =$BL$8-BL18 -> 0 | BO18: 11 | BP18: =Partici!I51 -> 0 | BQ18: =VLOOKUP(BP18,'DIA 8'!$B$59:$C$126,2,0) -> 0 | BR18: =$BQ$8-BQ18 -> 0 | BT18: 11 | BU18: =Partici!J51 -> 0 | BV18: =VLOOKUP(BU18,'DIA 9'!$B$59:$C$126,2,0) -> 0 | BW18: =$BV$8-BV18 -> 0 | BY18: 11 | BZ18: =Partici!K51 -> 0 | CA18: =VLOOKUP(BZ18,'DIA 10'!$B$59:$C$126,2,0) -> 0 | CB18: =$CA$8-CA18 -> 0 | CD18: 11 | CE18: =Partici!L51 -> 0 | CF18: =VLOOKUP(CE18,'DIA 11'!$B$59:$C$126,2,0) -> 0 | CG18: =$CF$8-CF18 -> 0 | CI18: 11 | CJ18: =Partici!M51 -> 0 | CK18: =VLOOKUP(CJ18,'DIA 12'!$B$59:$C$126,2,0) -> 0 | CL18: =$CK$8-CK18 -> 0 | CN18: 11 | CO18: =Partici!N51 -> 0 | CP18: =VLOOKUP(CO18,'24 12 23. CLUB'!$B$59:$C$126,2,0) -> 0 | CQ18: =$CP$8-CP18 -> 0
A19: 12 | B19: =+Partici!B11 -> KOKE | C19: ='DIA 1'!$AC$25 -> 9.7 | D19: ='DIA 2'!$AC$25 -> 0 | E19: ='DIA 3'!$AC$25 -> 0 | F19: ='DIA 4'!$AC$25 -> 0 | G19: ='DIA 5'!$AC$25 -> 0 | H19: ='DIA 6'!$AC$25 -> 0 | I19: ='DIA 7'!$AC$25 -> 0 | J19: ='DIA 8'!$AC$25 -> 0 | K19: ='DIA 9'!$AC$25 -> 0 | L19: ='DIA 10'!$AC$25 -> 0 | M19: ='DIA 11'!$AC$25 -> 0 | N19: ='DIA 12'!$AC$25 -> 0 | O19: ='24 12 23. CLUB'!$AC$25 -> 0 | P19: ='Dia14'!$AC$20 -> 0 | Q19: ='Dia15'!$AC$20 -> 0 | R19: ='Dia16'!$AC$20 -> 0 | S19: ='Dia17'!$AC$20 -> 0 | T19: ='Dia18'!$AC$20 -> 0 | U19: ='Dia19'!$AC$20 -> 0 | V19: ='Dia20'!$AC$20 -> 0 | W19: =SUM(Tabla1[[#This Row],[05-mar]:[10-jul20]]) -> 9.7 | X19: =$W$8-Tabla1[[#This Row],[TOTAL]] -> -8.6 | Z19: TRINIDAD | AA19: 16.3 | AB19: 38.8 | AC19: 47.1 | AD19: 72.2 | AF19: 12 | AG19: =Partici!B44 -> 0 | AH19: =VLOOKUP(AG19,'DIA 1'!#REF!,2,0) -> #REF! | AI19: =$AH$8-AH19 -> #REF! | AK19: 12 | AL19: =Partici!C38 -> 0 | AM19: =VLOOKUP(AL19,'DIA 2'!$B$59:$C$126,2,0) -> 0 | AN19: =$AM$8-AM19 -> 0 | AP19: 12 | AQ19: =Partici!D36 -> 0 | AR19: =VLOOKUP(AQ19,'DIA 3'!$B$59:$C$126,2,0) -> 0 | AS19: =$AR$8-AR19 -> 0 | AU19: 12 | AV19: =Partici!E40 -> 0 | AW19: =VLOOKUP(AV19,'DIA 4'!$B$59:$C$126,2,0) -> 0 | AX19: =$AW$8-AW19 -> 0 | AZ19: 12 | BA19: =Partici!F52 -> 0 | BB19: =VLOOKUP(BA19,'DIA 5'!$B$59:$C$126,2,0) -> 0 | BC19: =$BB$8-BB19 -> 0 | BE19: 12 | BF19: =Partici!G52 -> 0 | BG19: =VLOOKUP(BF19,'DIA 6'!$B$59:$C$126,2,0) -> 0 | BH19: =$BG$8-BG19 -> 0 | BJ19: 12 | BK19: =Partici!H52 -> 0 | BL19: =VLOOKUP(BK19,'DIA 7'!$B$59:$C$126,2,0) -> 0 | BM19: =$BL$8-BL19 -> 0 | BO19: 12 | BP19: =Partici!I52 -> 0 | BQ19: =VLOOKUP(BP19,'DIA 8'!$B$59:$C$126,2,0) -> 0 | BR19: =$BQ$8-BQ19 -> 0 | BT19: 12 | BU19: =Partici!J52 -> 0 | BV19: =VLOOKUP(BU19,'DIA 9'!$B$59:$C$126,2,0) -> 0 | BW19: =$BV$8-BV19 -> 0 | BY19: 12 | BZ19: =Partici!K52 -> 0 | CA19: =VLOOKUP(BZ19,'DIA 10'!$B$59:$C$126,2,0) -> 0 | CB19: =$CA$8-CA19 -> 0 | CD19: 12 | CE19: =Partici!L52 -> 0 | CF19: =VLOOKUP(CE19,'DIA 11'!$B$59:$C$126,2,0) -> 0 | CG19: =$CF$8-CF19 -> 0 | CI19: 12 | CJ19: =Partici!M52 -> 0 | CK19: =VLOOKUP(CJ19,'DIA 12'!$B$59:$C$126,2,0) -> 0 | CL19: =$CK$8-CK19 -> 0 | CN19: 12 | CO19: =Partici!N52 -> 0 | CP19: =VLOOKUP(CO19,'24 12 23. CLUB'!$B$59:$C$126,2,0) -> 0 | CQ19: =$CP$8-CP19 -> 0
A20: 13 | B20: =+Partici!B2 -> CAMPEON DE CAMPEONES | C20: ='DIA 1'!$AC$7 -> 3.9 | D20: ='DIA 2'!$AC$7 -> 0 | E20: ='DIA 3'!$AC$7 -> 0 | F20: ='DIA 4'!$AC$7 -> 0 | G20: ='DIA 5'!$AC$7 -> 0 | H20: ='DIA 6'!$AC$7 -> 0 | I20: ='DIA 7'!$AC$7 -> 0 | J20: ='DIA 8'!$AC$7 -> 0 | K20: ='DIA 9'!$AC$7 -> 0 | L20: ='DIA 10'!$AC$7 -> 0 | M20: ='DIA 11'!$AC$7 -> 0 | N20: ='DIA 12'!$AC$7 -> 0 | O20: ='24 12 23. CLUB'!$AC$7 -> 0 | P20: ='Dia14'!$AC$2 -> 0 | Q20: ='Dia15'!$AC$2 -> 0 | R20: ='Dia16'!$AC$2 -> 0 | S20: ='Dia17'!$AC$2 -> 0 | T20: ='Dia18'!$AC$2 -> 0 | U20: ='Dia19'!$AC$2 -> 0 | V20: ='Dia20'!$AC$2 -> 0 | W20: =SUM(Tabla1[[#This Row],[05-mar]:[10-jul20]]) -> 3.9 | X20: =$W$8-Tabla1[[#This Row],[TOTAL]] -> -2.8 | Z20: LOINO | AA20: 34.8 | AB20: 28.3 | AC20: 78.9 | AD20: 31.9 | AF20: 13 | AG20: =Partici!B50 -> 0 | AH20: =VLOOKUP(AG20,'DIA 1'!#REF!,2,0) -> #REF! | AI20: =$BB$8-AH20 -> #REF! | AK20: 13 | AL20: =Partici!C47 -> 0 | AM20: =VLOOKUP(AL20,'DIA 2'!$B$59:$C$126,2,0) -> 0 | AN20: =$BG$8-AM20 -> 0 | AP20: 13 | AQ20: =Partici!D47 -> 0 | AR20: =VLOOKUP(AQ20,'DIA 3'!$B$59:$C$126,2,0) -> 0 | AS20: =$AR$8-AR20 -> 0 | AU20: 13 | AV20: =Partici!E36 -> 0 | AW20: =VLOOKUP(AV20,'DIA 4'!$B$59:$C$126,2,0) -> 0 | AX20: =$AW$8-AW20 -> 0 | AZ20: 13 | BA20: =Partici!F42 -> 0 | BB20: =VLOOKUP(BA20,'DIA 5'!$B$59:$C$126,2,0) -> 0 | BC20: =$BB$8-BB20 -> 0 | BE20: 13 | BF20: =Partici!G42 -> 0 | BG20: =VLOOKUP(BF20,'DIA 6'!$B$59:$C$126,2,0) -> 0 | BH20: =$BG$8-BG20 -> 0 | BJ20: 13 | BK20: =Partici!H42 -> 0 | BL20: =VLOOKUP(BK20,'DIA 7'!$B$59:$C$126,2,0) -> 0 | BM20: =$BL$8-BL20 -> 0 | BO20: 13 | BP20: =Partici!I42 -> 0 | BQ20: =VLOOKUP(BP20,'DIA 8'!$B$59:$C$126,2,0) -> 0 | BR20: =$BQ$8-BQ20 -> 0 | BT20: 13 | BU20: =Partici!J42 -> 0 | BV20: =VLOOKUP(BU20,'DIA 9'!$B$59:$C$126,2,0) -> 0 | BW20: =$BV$8-BV20 -> 0 | BY20: 13 | BZ20: =Partici!K42 -> 0 | CA20: =VLOOKUP(BZ20,'DIA 10'!$B$59:$C$126,2,0) -> 0 | CB20: =$CA$8-CA20 -> 0 | CD20: 13 | CE20: =Partici!L42 -> 0 | CF20: =VLOOKUP(CE20,'DIA 11'!$B$59:$C$126,2,0) -> 0 | CG20: =$CF$8-CF20 -> 0 | CI20: 13 | CJ20: =Partici!M42 -> 0 | CK20: =VLOOKUP(CJ20,'DIA 12'!$B$59:$C$126,2,0) -> 0 | CL20: =$CK$8-CK20 -> 0 | CN20: 13 | CO20: =Partici!N42 -> 0 | CP20: =VLOOKUP(CO20,'24 12 23. CLUB'!$B$59:$C$126,2,0) -> 0 | CQ20: =$CP$8-CP20 -> 0
A21: 14 | B21: =+Partici!B3 -> FERNANDA | C21: ='DIA 1'!$AC$9 -> 1.1 | D21: ='DIA 2'!$AC$9 -> 0 | E21: ='DIA 3'!$AC$9 -> 0 | F21: ='DIA 4'!$AC$9 -> 0 | G21: ='DIA 5'!$AC$9 -> 0 | H21: ='DIA 6'!$AC$9 -> 0 | I21: ='DIA 7'!$AC$9 -> 0 | J21: ='DIA 8'!$AC$9 -> 0 | K21: ='DIA 9'!$AC$9 -> 0 | L21: ='DIA 10'!$AC$9 -> 0 | M21: ='DIA 11'!$AC$9 -> 0 | N21: ='DIA 12'!$AC$9 -> 0 | O21: ='24 12 23. CLUB'!$AC$9 -> 0 | P21: ='Dia14'!$AC$4 -> 0 | Q21: ='Dia15'!$AC$4 -> 0 | R21: ='Dia16'!$AC$4 -> 0 | S21: ='Dia17'!$AC$4 -> 0 | T21: ='Dia18'!$AC$4 -> 0 | U21: ='Dia19'!$AC$4 -> 0 | V21: ='Dia20'!$AC$4 -> 0 | W21: =SUM(Tabla1[[#This Row],[05-mar]:[10-jul20]]) -> 1.1 | X21: =$W$8-Tabla1[[#This Row],[TOTAL]] -> 0 | Z21: CHOLITO | AA21: 11.3 | AB21: 50.8 | AC21: 68.4 | AD21: 40.3 | AF21: 14 | AG21: =Partici!B48 -> 0 | AH21: =VLOOKUP(AG21,'DIA 1'!#REF!,2,0) -> #REF! | AI21: =$BB$8-AH21 -> #REF! | AK21: 14 | AL21: =Partici!C52 -> 0 | AM21: =VLOOKUP(AL21,'DIA 2'!$B$59:$C$126,2,0) -> 0 | AN21: =$BG$8-AM21 -> 0 | AP21: 14 | AQ21: =Partici!D43 -> 0 | AR21: =VLOOKUP(AQ21,'DIA 3'!$B$59:$C$126,2,0) -> 0 | AS21: =$AR$8-AR21 -> 0 | AU21: 14 | AV21: =Partici!E55 -> 0 | AW21: =VLOOKUP(AV21,'DIA 4'!$B$59:$C$126,2,0) -> 0 | AX21: =$AW$8-AW21 -> 0 | AZ21: 14 | BA21: =Partici!F56 -> 0 | BB21: =VLOOKUP(BA21,'DIA 5'!$B$59:$C$126,2,0) -> 0 | BC21: =$BB$8-BB21 -> 0 | BE21: 14 | BF21: =Partici!G56 -> 0 | BG21: =VLOOKUP(BF21,'DIA 6'!$B$59:$C$126,2,0) -> 0 | BH21: =$BG$8-BG21 -> 0 | BJ21: 14 | BK21: =Partici!H56 -> 0 | BL21: =VLOOKUP(BK21,'DIA 7'!$B$59:$C$126,2,0) -> 0 | BM21: =$BL$8-BL21 -> 0 | BO21: 14 | BP21: =Partici!I56 -> 0 | BQ21: =VLOOKUP(BP21,'DIA 8'!$B$59:$C$126,2,0) -> 0 | BR21: =$BQ$8-BQ21 -> 0 | BT21: 14 | BU21: =Partici!J56 -> 0 | BV21: =VLOOKUP(BU21,'DIA 9'!$B$59:$C$126,2,0) -> 0 | BW21: =$BV$8-BV21 -> 0 | BY21: 14 | BZ21: =Partici!K56 -> 0 | CA21: =VLOOKUP(BZ21,'DIA 10'!$B$59:$C$126,2,0) -> 0 | CB21: =$CA$8-CA21 -> 0 | CD21: 14 | CE21: =Partici!L56 -> 0 | CF21: =VLOOKUP(CE21,'DIA 11'!$B$59:$C$126,2,0) -> 0 | CG21: =$CF$8-CF21 -> 0 | CI21: 14 | CJ21: =Partici!M56 -> 0 | CK21: =VLOOKUP(CJ21,'DIA 12'!$B$59:$C$126,2,0) -> 0 | CL21: =$CK$8-CK21 -> 0 | CN21: 14 | CO21: =Partici!N56 -> 0 | CP21: =VLOOKUP(CO21,'24 12 23. CLUB'!$B$59:$C$126,2,0) -> 0 | CQ21: =$CP$8-CP21 -> 0
A22: 15 | B22: =+Partici!B13 -> ALF | C22: ='DIA 1'!$AC$29 -> 0 | D22: ='DIA 2'!$AC$29 -> 0 | E22: ='DIA 3'!$AC$29 -> 0 | F22: ='DIA 4'!$AC$29 -> 0 | G22: ='DIA 5'!$AC$29 -> 0 | H22: ='DIA 6'!$AC$29 -> 0 | I22: ='DIA 7'!$AC$29 -> 0 | J22: ='DIA 8'!$AC$29 -> 0 | K22: ='DIA 9'!$AC$29 -> 0 | L22: ='DIA 10'!$AC$29 -> 0 | M22: ='DIA 11'!$AC$29 -> 0 | N22: ='DIA 12'!$AC$29 -> 0 | O22: ='24 12 23. CLUB'!$AC$29 -> 0 | P22: ='Dia14'!$AC$24 -> 0 | Q22: ='Dia15'!$AC$24 -> 0 | R22: ='Dia16'!$AC$24 -> 0 | S22: ='Dia17'!$AC$24 -> 0 | T22: ='Dia18'!$AC$24 -> 0 | U22: ='Dia19'!$AC$24 -> 0 | V22: ='Dia20'!$AC$24 -> 0 | W22: =SUM(Tabla1[[#This Row],[05-mar]:[10-jul20]]) -> 0 | X22: =$W$8-Tabla1[[#This Row],[TOTAL]] -> 1.1 | Z22: STORMILORD | AA22: 70.5 | AB22: 44.6 | AC22: 22.1 | AD22: 26.5 | AF22: 15 | AG22: =Partici!B47 -> 0 | AH22: =VLOOKUP(AG22,'DIA 1'!#REF!,2,0) -> #REF! | AI22: =$BB$8-AH22 -> #REF! | AK22: 15 | AL22: =Partici!C48 -> 0 | AM22: =VLOOKUP(AL22,'DIA 2'!$B$59:$C$126,2,0) -> 0 | AN22: =$BG$8-AM22 -> 0 | AP22: 15 | AQ22: =Partici!D38 -> 0 | AR22: =VLOOKUP(AQ22,'DIA 3'!$B$59:$C$126,2,0) -> 0 | AS22: =$AR$8-AR22 -> 0 | AU22: 15 | AV22: =Partici!E50 -> 0 | AW22: =VLOOKUP(AV22,'DIA 4'!$B$59:$C$126,2,0) -> 0 | AX22: =$AW$8-AW22 -> 0 | AZ22: 15 | BA22: =Partici!F49 -> 0 | BB22: =VLOOKUP(BA22,'DIA 5'!$B$59:$C$126,2,0) -> 0 | BC22: =$BB$8-BB22 -> 0 | BE22: 15 | BF22: =Partici!G49 -> 0 | BG22: =VLOOKUP(BF22,'DIA 6'!$B$59:$C$126,2,0) -> 0 | BH22: =$BG$8-BG22 -> 0 | BJ22: 15 | BK22: =Partici!H49 -> 0 | BL22: =VLOOKUP(BK22,'DIA 7'!$B$59:$C$126,2,0) -> 0 | BM22: =$BL$8-BL22 -> 0 | BO22: 15 | BP22: =Partici!I49 -> 0 | BQ22: =VLOOKUP(BP22,'DIA 8'!$B$59:$C$126,2,0) -> 0 | BR22: =$BQ$8-BQ22 -> 0 | BT22: 15 | BU22: =Partici!J49 -> 0 | BV22: =VLOOKUP(BU22,'DIA 9'!$B$59:$C$126,2,0) -> 0 | BW22: =$BV$8-BV22 -> 0 | BY22: 15 | BZ22: =Partici!K49 -> 0 | CA22: =VLOOKUP(BZ22,'DIA 10'!$B$59:$C$126,2,0) -> 0 | CB22: =$CA$8-CA22 -> 0 | CD22: 15 | CE22: =Partici!L49 -> 0 | CF22: =VLOOKUP(CE22,'DIA 11'!$B$59:$C$126,2,0) -> 0 | CG22: =$CF$8-CF22 -> 0 | CI22: 15 | CJ22: =Partici!M49 -> 0 | CK22: =VLOOKUP(CJ22,'DIA 12'!$B$59:$C$126,2,0) -> 0 | CL22: =$CK$8-CK22 -> 0 | CN22: 15 | CO22: =Partici!N49 -> 0 | CP22: =VLOOKUP(CO22,'24 12 23. CLUB'!$B$59:$C$126,2,0) -> 0 | CQ22: =$CP$8-CP22 -> 0
A23: 16 | B23: =+Partici!B5 -> OVAYORK | C23: ='DIA 1'!$AC$13 -> 0 | D23: ='DIA 2'!$AC$13 -> 0 | E23: ='DIA 3'!$AC$13 -> 0 | F23: ='DIA 4'!$AC$13 -> 0 | G23: ='DIA 5'!$AC$13 -> 0 | H23: ='DIA 6'!$AC$13 -> 0 | I23: ='DIA 7'!$AC$13 -> 0 | J23: ='DIA 8'!$AC$13 -> 0 | K23: ='DIA 9'!$AC$13 -> 0 | L23: ='DIA 10'!$AC$13 -> 0 | M23: ='DIA 11'!$AC$13 -> 0 | N23: ='DIA 12'!$AC$13 -> 0 | O23: ='24 12 23. CLUB'!$AC$13 -> 0 | P23: ='Dia14'!$AC$8 -> 0 | Q23: ='Dia15'!$AC$8 -> 0 | R23: ='Dia16'!$AC$8 -> 0 | S23: ='Dia17'!$AC$8 -> 0 | T23: ='Dia18'!$AC$8 -> 0 | U23: ='Dia19'!$AC$8 -> 0 | V23: ='Dia20'!$AC$8 -> 0 | W23: =SUM(Tabla1[[#This Row],[05-mar]:[10-jul20]]) -> 0 | X23: =$W$8-Tabla1[[#This Row],[TOTAL]] -> 1.1 | Z23: ARRE DEMONIO | AA23: 28.1 | AB23: 36 | AC23: 54 | AD23: 44.9 | AF23: 16 | AG23: =Partici!B51 -> 0 | AH23: =VLOOKUP(AG23,'DIA 1'!#REF!,2,0) -> #REF! | AI23: =$BB$8-AH23 -> #REF! | AK23: 16 | AL23: =Partici!C51 -> 0 | AM23: =VLOOKUP(AL23,'DIA 2'!$B$59:$C$126,2,0) -> 0 | AN23: =$BG$8-AM23 -> 0 | AP23: 16 | AQ23: =Partici!D51 -> 0 | AR23: =VLOOKUP(AQ23,'DIA 3'!$B$59:$C$126,2,0) -> 0 | AS23: =$AR$8-AR23 -> 0 | AU23: 16 | AV23: =Partici!E48 -> 0 | AW23: =VLOOKUP(AV23,'DIA 4'!$B$59:$C$126,2,0) -> 0 | AX23: =$AW$8-AW23 -> 0 | AZ23: 16 | BA23: =Partici!F54 -> 0 | BB23: =VLOOKUP(BA23,'DIA 5'!$B$59:$C$126,2,0) -> 0 | BC23: =$BB$8-BB23 -> 0 | BE23: 16 | BF23: =Partici!G54 -> 0 | BG23: =VLOOKUP(BF23,'DIA 6'!$B$59:$C$126,2,0) -> 0 | BH23: =$BG$8-BG23 -> 0 | BJ23: 16 | BK23: =Partici!H54 -> 0 | BL23: =VLOOKUP(BK23,'DIA 7'!$B$59:$C$126,2,0) -> 0 | BM23: =$BL$8-BL23 -> 0 | BO23: 16 | BP23: =Partici!I54 -> 0 | BQ23: =VLOOKUP(BP23,'DIA 8'!$B$59:$C$126,2,0) -> 0 | BR23: =$BQ$8-BQ23 -> 0 | BT23: 16 | BU23: =Partici!J54 -> 0 | BV23: =VLOOKUP(BU23,'DIA 9'!$B$59:$C$126,2,0) -> 0 | BW23: =$BV$8-BV23 -> 0 | BY23: 16 | BZ23: =Partici!K54 -> 0 | CA23: =VLOOKUP(BZ23,'DIA 10'!$B$59:$C$126,2,0) -> 0 | CB23: =$CA$8-CA23 -> 0 | CD23: 16 | CE23: =Partici!L54 -> 0 | CF23: =VLOOKUP(CE23,'DIA 11'!$B$59:$C$126,2,0) -> 0 | CG23: =$CF$8-CF23 -> 0 | CI23: 16 | CJ23: =Partici!M54 -> 0 | CK23: =VLOOKUP(CJ23,'DIA 12'!$B$59:$C$126,2,0) -> 0 | CL23: =$CK$8-CK23 -> 0 | CN23: 16 | CO23: =Partici!N54 -> 0 | CP23: =VLOOKUP(CO23,'24 12 23. CLUB'!$B$59:$C$126,2,0) -> 0 | CQ23: =$CP$8-CP23 -> 0
A24: 17 | B24: =+Partici!B7 -> KING JORANTO | C24: ='DIA 1'!$AC$17 -> 0 | D24: ='DIA 2'!$AC$17 -> 0 | E24: ='DIA 3'!$AC$17 -> 0 | F24: ='DIA 4'!$AC$17 -> 0 | G24: ='DIA 5'!$AC$17 -> 0 | H24: ='DIA 6'!$AC$17 -> 0 | I24: ='DIA 7'!$AC$17 -> 0 | J24: ='DIA 8'!$AC$17 -> 0 | K24: ='DIA 9'!$AC$17 -> 0 | L24: ='DIA 10'!$AC$17 -> 0 | M24: ='DIA 11'!$AC$17 -> 0 | N24: ='DIA 12'!$AC$17 -> 0 | O24: ='24 12 23. CLUB'!$AC$17 -> 0 | P24: ='Dia14'!$AC$12 -> 0 | Q24: ='Dia15'!$AC$12 -> 0 | R24: ='Dia16'!$AC$12 -> 0 | S24: ='Dia17'!$AC$12 -> 0 | T24: ='Dia18'!$AC$12 -> 0 | U24: ='Dia19'!$AC$12 -> 0 | V24: ='Dia20'!$AC$12 -> 0 | W24: =SUM(Tabla1[[#This Row],[05-mar]:[10-jul20]]) -> 0 | X24: =$W$8-Tabla1[[#This Row],[TOTAL]] -> 1.1 | Z24: ROMATRI | AA24: 44.4 | AB24: 47.3 | AC24: 30.5 | AD24: 40.2 | AF24: 17 | AG24: =Partici!B49 -> 0 | AH24: =VLOOKUP(AG24,'DIA 1'!#REF!,2,0) -> #REF! | AI24: =$BB$8-AH24 -> #REF! | AK24: 17 | AL24: =Partici!C50 -> 0 | AM24: =VLOOKUP(AL24,'DIA 2'!$B$59:$C$126,2,0) -> 0 | AN24: =$BG$8-AM24 -> 0 | AP24: 17 | AQ24: =Partici!D55 -> 0 | AR24: =VLOOKUP(AQ24,'DIA 3'!$B$59:$C$126,2,0) -> 0 | AS24: =$AR$8-AR24 -> 0 | AU24: 17 | AV24: =Partici!E51 -> 0 | AW24: =VLOOKUP(AV24,'DIA 4'!$B$59:$C$126,2,0) -> 0 | AX24: =$AW$8-AW24 -> 0 | AZ24: 17 | BA24: =Partici!F37 -> 0 | BB24: =VLOOKUP(BA24,'DIA 5'!$B$59:$C$126,2,0) -> 0 | BC24: =$BB$8-BB24 -> 0 | BE24: 17 | BF24: =Partici!G37 -> 0 | BG24: =VLOOKUP(BF24,'DIA 6'!$B$59:$C$126,2,0) -> 0 | BH24: =$BG$8-BG24 -> 0 | BJ24: 17 | BK24: =Partici!H37 -> 0 | BL24: =VLOOKUP(BK24,'DIA 7'!$B$59:$C$126,2,0) -> 0 | BM24: =$BL$8-BL24 -> 0 | BO24: 17 | BP24: =Partici!I37 -> 0 | BQ24: =VLOOKUP(BP24,'DIA 8'!$B$59:$C$126,2,0) -> 0 | BR24: =$BQ$8-BQ24 -> 0 | BT24: 17 | BU24: =Partici!J37 -> 0 | BV24: =VLOOKUP(BU24,'DIA 9'!$B$59:$C$126,2,0) -> 0 | BW24: =$BV$8-BV24 -> 0 | BY24: 17 | BZ24: =Partici!K37 -> 0 | CA24: =VLOOKUP(BZ24,'DIA 10'!$B$59:$C$126,2,0) -> 0 | CB24: =$CA$8-CA24 -> 0 | CD24: 17 | CE24: =Partici!L37 -> 0 | CF24: =VLOOKUP(CE24,'DIA 11'!$B$59:$C$126,2,0) -> 0 | CG24: =$CF$8-CF24 -> 0 | CI24: 17 | CJ24: =Partici!M37 -> 0 | CK24: =VLOOKUP(CJ24,'DIA 12'!$B$59:$C$126,2,0) -> 0 | CL24: =$CK$8-CK24 -> 0 | CN24: 17 | CO24: =Partici!N37 -> 0 | CP24: =VLOOKUP(CO24,'24 12 23. CLUB'!$B$59:$C$126,2,0) -> 0 | CQ24: =$CP$8-CP24 -> 0
A25: 18 | B25: =+Partici!B10 -> MAGICO MEDINA | C25: ='DIA 1'!$AC$23 -> 1.1 | D25: ='DIA 2'!$AC$23 -> 0 | E25: ='DIA 3'!$AC$23 -> 0 | F25: ='DIA 4'!$AC$23 -> 0 | G25: ='DIA 5'!$AC$23 -> 0 | H25: ='DIA 6'!$AC$23 -> 0 | I25: ='DIA 7'!$AC$23 -> 0 | J25: ='DIA 8'!$AC$23 -> 0 | K25: ='DIA 9'!$AC$23 -> 0 | L25: ='DIA 10'!$AC$23 -> 0 | M25: ='DIA 11'!$AC$23 -> 0 | N25: ='DIA 12'!$AC$23 -> 0 | O25: ='24 12 23. CLUB'!$AC$23 -> 0 | P25: ='Dia14'!$AC$18 -> 0 | Q25: ='Dia15'!$AC$18 -> 0 | R25: ='Dia16'!$AC$18 -> 0 | S25: ='Dia17'!$AC$18 -> 0 | T25: ='Dia18'!$AC$18 -> 0 | U25: ='Dia19'!$AC$18 -> 0 | V25: ='Dia20'!$AC$18 -> 0 | W25: =SUM(Tabla1[[#This Row],[05-mar]:[10-jul20]]) -> 1.1 | X25: =$W$8-Tabla1[[#This Row],[TOTAL]] -> 0 | Z25: TALIVAN | AA25: 37.6 | AB25: 33.4 | AC25: 52.3 | AD25: 31.9 | AF25: 18 | AG25: =Partici!B52 -> 0 | AH25: =VLOOKUP(AG25,'DIA 1'!#REF!,2,0) -> #REF! | AI25: =$BB$8-AH25 -> #REF! | AK25: 18 | AL25: =Partici!C49 -> 0 | AM25: =VLOOKUP(AL25,'DIA 2'!$B$59:$C$126,2,0) -> 0 | AN25: =$BG$8-AM25 -> 0 | AP25: 18 | AQ25: =Partici!D58 -> 0 | AR25: =VLOOKUP(AQ25,'DIA 3'!$B$59:$C$126,2,0) -> 0 | AS25: =$AR$8-AR25 -> 0 | AU25: 18 | AV25: =Partici!E52 -> 0 | AW25: =VLOOKUP(AV25,'DIA 4'!$B$59:$C$126,2,0) -> 0 | AX25: =$AW$8-AW25 -> 0 | AZ25: 18 | BA25: =Partici!F53 -> 0 | BB25: =VLOOKUP(BA25,'DIA 5'!$B$59:$C$126,2,0) -> 0 | BC25: =$BB$8-BB25 -> 0 | BE25: 18 | BF25: =Partici!G53 -> 0 | BG25: =VLOOKUP(BF25,'DIA 6'!$B$59:$C$126,2,0) -> 0 | BH25: =$BG$8-BG25 -> 0 | BJ25: 18 | BK25: =Partici!H53 -> 0 | BL25: =VLOOKUP(BK25,'DIA 7'!$B$59:$C$126,2,0) -> 0 | BM25: =$BL$8-BL25 -> 0 | BO25: 18 | BP25: =Partici!I53 -> 0 | BQ25: =VLOOKUP(BP25,'DIA 8'!$B$59:$C$126,2,0) -> 0 | BR25: =$BQ$8-BQ25 -> 0 | BT25: 18 | BU25: =Partici!J53 -> 0 | BV25: =VLOOKUP(BU25,'DIA 9'!$B$59:$C$126,2,0) -> 0 | BW25: =$BV$8-BV25 -> 0 | BY25: 18 | BZ25: =Partici!K53 -> 0 | CA25: =VLOOKUP(BZ25,'DIA 10'!$B$59:$C$126,2,0) -> 0 | CB25: =$CA$8-CA25 -> 0 | CD25: 18 | CE25: =Partici!L53 -> 0 | CF25: =VLOOKUP(CE25,'DIA 11'!$B$59:$C$126,2,0) -> 0 | CG25: =$CF$8-CF25 -> 0 | CI25: 18 | CJ25: =Partici!M53 -> 0 | CK25: =VLOOKUP(CJ25,'DIA 12'!$B$59:$C$126,2,0) -> 0 | CL25: =$CK$8-CK25 -> 0 | CN25: 18 | CO25: =Partici!N53 -> 0 | CP25: =VLOOKUP(CO25,'24 12 23. CLUB'!$B$59:$C$126,2,0) -> 0 | CQ25: =$CP$8-CP25 -> 0
A26: 19 | B26: =+Partici!B8 -> TOCOCO | C26: ='DIA 1'!$AC$19 -> 9.7 | D26: ='DIA 2'!$AC$19 -> 0 | E26: ='DIA 3'!$AC$19 -> 0 | F26: ='DIA 4'!$AC$19 -> 0 | G26: ='DIA 5'!$AC$19 -> 0 | H26: ='DIA 6'!$AC$19 -> 0 | I26: ='DIA 7'!$AC$19 -> 0 | J26: ='DIA 8'!$AC$19 -> 0 | K26: ='DIA 9'!$AC$19 -> 0 | L26: ='DIA 10'!$AC$19 -> 0 | M26: ='DIA 11'!$AC$19 -> 0 | N26: ='DIA 12'!$AC$19 -> 0 | O26: ='24 12 23. CLUB'!$AC$19 -> 0 | P26: ='Dia14'!$AC$14 -> 0 | Q26: ='Dia15'!$AC$14 -> 0 | R26: ='Dia16'!$AC$14 -> 0 | S26: ='Dia17'!$AC$14 -> 0 | T26: ='Dia18'!$AC$14 -> 0 | U26: ='Dia19'!$AC$14 -> 0 | V26: ='Dia20'!$AC$14 -> 0 | W26: =SUM(Tabla1[[#This Row],[05-mar]:[10-jul20]]) -> 9.7 | X26: =$W$8-Tabla1[[#This Row],[TOTAL]] -> -8.6 | Z26: MATILDE | AA26: 46.9 | AB26: 34.2 | AC26: 31.7 | AD26: 22.4 | AF26: 19 | AG26: =Partici!B53 -> 0 | AH26: =VLOOKUP(AG26,'DIA 1'!#REF!,2,0) -> #REF! | AI26: =$BB$8-AH26 -> #REF! | AK26: 19 | AL26: =Partici!C53 -> 0 | AM26: =VLOOKUP(AL26,'DIA 2'!$B$59:$C$126,2,0) -> 0 | AN26: =$BG$8-AM26 -> 0 | AP26: 19 | AQ26: =Partici!D53 -> 0 | AR26: =VLOOKUP(AQ26,'DIA 3'!$B$59:$C$126,2,0) -> 0 | AS26: =$AR$8-AR26 -> 0 | AU26: 19 | AV26: =Partici!E56 -> 0 | AW26: =VLOOKUP(AV26,'DIA 4'!$B$59:$C$126,2,0) -> 0 | AX26: =$AW$8-AW26 -> 0 | AZ26: 19 | BA26: =Partici!F39 -> 0 | BB26: =VLOOKUP(BA26,'DIA 5'!$B$59:$C$126,2,0) -> 0 | BC26: =$BB$8-BB26 -> 0 | BE26: 19 | BF26: =Partici!G39 -> 0 | BG26: =VLOOKUP(BF26,'DIA 6'!$B$59:$C$126,2,0) -> 0 | BH26: =$BG$8-BG26 -> 0 | BJ26: 19 | BK26: =Partici!H39 -> 0 | BL26: =VLOOKUP(BK26,'DIA 7'!$B$59:$C$126,2,0) -> 0 | BM26: =$BL$8-BL26 -> 0 | BO26: 19 | BP26: =Partici!I39 -> 0 | BQ26: =VLOOKUP(BP26,'DIA 8'!$B$59:$C$126,2,0) -> 0 | BR26: =$BQ$8-BQ26 -> 0 | BT26: 19 | BU26: =Partici!J39 -> 0 | BV26: =VLOOKUP(BU26,'DIA 9'!$B$59:$C$126,2,0) -> 0 | BW26: =$BV$8-BV26 -> 0 | BY26: 19 | BZ26: =Partici!K39 -> 0 | CA26: =VLOOKUP(BZ26,'DIA 10'!$B$59:$C$126,2,0) -> 0 | CB26: =$CA$8-CA26 -> 0 | CD26: 19 | CE26: =Partici!L39 -> 0 | CF26: =VLOOKUP(CE26,'DIA 11'!$B$59:$C$126,2,0) -> 0 | CG26: =$CF$8-CF26 -> 0 | CI26: 19 | CJ26: =Partici!M39 -> 0 | CK26: =VLOOKUP(CJ26,'DIA 12'!$B$59:$C$126,2,0) -> 0 | CL26: =$CK$8-CK26 -> 0 | CN26: 19 | CO26: =Partici!N39 -> 0 | CP26: =VLOOKUP(CO26,'24 12 23. CLUB'!$B$59:$C$126,2,0) -> 0 | CQ26: =$CP$8-CP26 -> 0
A27: 20 | B27: =+Partici!B21 -> SANVI | C27: ='DIA 1'!$AC$45 -> 1.1 | D27: ='DIA 2'!$AC$45 -> 0 | E27: ='DIA 3'!$AC$45 -> 0 | F27: ='DIA 4'!$AC$45 -> 0 | G27: ='DIA 5'!$AC$45 -> 0 | H27: ='DIA 6'!$AC$45 -> 0 | I27: ='DIA 7'!$AC$45 -> 0 | J27: ='DIA 8'!$AC$45 -> 0 | K27: ='DIA 9'!$AC$45 -> 0 | L27: ='DIA 10'!$AC$45 -> 0 | M27: ='DIA 11'!$AC$45 -> 0 | N27: ='DIA 12'!$AC$45 -> 0 | O27: ='24 12 23. CLUB'!$AC$45 -> 0 | P27: ='Dia14'!$AC$40 -> 0 | Q27: ='Dia15'!$AC$40 -> 0 | R27: ='Dia16'!$AC$40 -> 0 | S27: ='Dia17'!$AC$40 -> 0 | T27: ='Dia18'!$AC$40 -> 0 | U27: ='Dia19'!$AC$40 -> 0 | V27: ='Dia20'!$AC$40 -> 0 | W27: =SUM(Tabla1[[#This Row],[05-mar]:[10-jul20]]) -> 1.1 | X27: =$W$8-Tabla1[[#This Row],[TOTAL]] -> 0 | Z27: REMY | AA27: 30 | AB27: 23.2 | AC27: 43.7 | AD27: 32.6 | AF27: 20 | AG27: =Partici!B54 -> 0 | AH27: =VLOOKUP(AG27,'DIA 1'!#REF!,2,0) -> #REF! | AI27: =$BB$8-AH27 -> #REF! | AK27: 20 | AL27: =Partici!C54 -> 0 | AM27: =VLOOKUP(AL27,'DIA 2'!$B$59:$C$126,2,0) -> 0 | AN27: =$BG$8-AM27 -> 0 | AP27: 20 | AQ27: =Partici!D52 -> 0 | AR27: =VLOOKUP(AQ27,'DIA 3'!$B$59:$C$126,2,0) -> 0 | AS27: =$AR$8-AR27 -> 0 | AU27: 20 | AV27: =Partici!E49 -> 0 | AW27: =VLOOKUP(AV27,'DIA 4'!$B$59:$C$126,2,0) -> 0 | AX27: =$AW$8-AW27 -> 0 | AZ27: 20 | BA27: =Partici!F46 -> 0 | BB27: =VLOOKUP(BA27,'DIA 5'!$B$59:$C$126,2,0) -> 0 | BC27: =$BB$8-BB27 -> 0 | BE27: 20 | BF27: =Partici!G46 -> 0 | BG27: =VLOOKUP(BF27,'DIA 6'!$B$59:$C$126,2,0) -> 0 | BH27: =$BG$8-BG27 -> 0 | BJ27: 20 | BK27: =Partici!H46 -> 0 | BL27: =VLOOKUP(BK27,'DIA 7'!$B$59:$C$126,2,0) -> 0 | BM27: =$BL$8-BL27 -> 0 | BO27: 20 | BP27: =Partici!I46 -> 0 | BQ27: =VLOOKUP(BP27,'DIA 8'!$B$59:$C$126,2,0) -> 0 | BR27: =$BQ$8-BQ27 -> 0 | BT27: 20 | BU27: =Partici!J46 -> 0 | BV27: =VLOOKUP(BU27,'DIA 9'!$B$59:$C$126,2,0) -> 0 | BW27: =$BV$8-BV27 -> 0 | BY27: 20 | BZ27: =Partici!K46 -> 0 | CA27: =VLOOKUP(BZ27,'DIA 10'!$B$59:$C$126,2,0) -> 0 | CB27: =$CA$8-CA27 -> 0 | CD27: 20 | CE27: =Partici!L46 -> 0 | CF27: =VLOOKUP(CE27,'DIA 11'!$B$59:$C$126,2,0) -> 0 | CG27: =$CF$8-CF27 -> 0 | CI27: 20 | CJ27: =Partici!M46 -> 0 | CK27: =VLOOKUP(CJ27,'DIA 12'!$B$59:$C$126,2,0) -> 0 | CL27: =$CK$8-CK27 -> 0 | CN27: 20 | CO27: =Partici!N46 -> 0 | CP27: =VLOOKUP(CO27,'24 12 23. CLUB'!$B$59:$C$126,2,0) -> 0 | CQ27: =$CP$8-CP27 -> 0
A28: 21 | B28: =+Partici!B23 -> SIN FE-IA | C28: ='DIA 1'!$AC$49 -> 3.9 | D28: ='DIA 2'!$AC$49 -> 0 | E28: ='DIA 3'!$AC$49 -> 0 | F28: ='DIA 4'!$AC$49 -> 0 | G28: ='DIA 5'!$AC$49 -> 0 | H28: ='DIA 6'!$AC$49 -> 0 | I28: ='DIA 7'!$AC$49 -> 0 | J28: ='DIA 8'!$AC$49 -> 0 | K28: ='DIA 9'!$AC$49 -> 0 | L28: ='DIA 10'!$AC$49 -> 0 | M28: ='DIA 11'!$AC$49 -> 0 | N28: ='DIA 12'!$AC$49 -> 0 | O28: ='24 12 23. CLUB'!$AC$49 -> 0 | P28: ='Dia14'!$AC$44 -> 0 | Q28: ='Dia15'!$AC$44 -> 0 | R28: ='Dia16'!$AC$44 -> 0 | S28: ='Dia17'!$AC$44 -> 0 | T28: ='Dia18'!$AC$44 -> 0 | U28: ='Dia19'!$AC$44 -> 0 | V28: ='Dia20'!$AC$44 -> 0 | W28: =SUM(Tabla1[[#This Row],[05-mar]:[10-jul20]]) -> 3.9 | X28: =$W$8-Tabla1[[#This Row],[TOTAL]] -> -2.8 | Z28: SALAMANCA | AA28: 23.4 | AB28: 42.6 | AC28: 33.2 | AD28: 29.4 | AF28: 21 | AG28: =Partici!B55 -> 0 | AH28: =VLOOKUP(AG28,'DIA 1'!#REF!,2,0) -> #REF! | AI28: =$BB$8-AH28 -> #REF! | AK28: 21 | AL28: =Partici!C55 -> 0 | AM28: =VLOOKUP(AL28,'DIA 2'!$B$59:$C$126,2,0) -> 0 | AN28: =$BG$8-AM28 -> 0 | AP28: 21 | AQ28: =Partici!D54 -> 0 | AR28: =VLOOKUP(AQ28,'DIA 3'!$B$59:$C$126,2,0) -> 0 | AS28: =$AR$8-AR28 -> 0 | AU28: 21 | AV28: =Partici!E54 -> 0 | AW28: =VLOOKUP(AV28,'DIA 4'!$B$59:$C$126,2,0) -> 0 | AX28: =$AW$8-AW28 -> 0 | AZ28: 21 | BA28: =Partici!F35 -> 0 | BB28: =VLOOKUP(BA28,'DIA 5'!$B$59:$C$126,2,0) -> 0 | BC28: =$BB$8-BB28 -> 0 | BE28: 21 | BF28: =Partici!G35 -> 0 | BG28: =VLOOKUP(BF28,'DIA 6'!$B$59:$C$126,2,0) -> 0 | BH28: =$BG$8-BG28 -> 0 | BJ28: 21 | BK28: =Partici!H35 -> 0 | BL28: =VLOOKUP(BK28,'DIA 7'!$B$59:$C$126,2,0) -> 0 | BM28: =$BL$8-BL28 -> 0 | BO28: 21 | BP28: =Partici!I35 -> 0 | BQ28: =VLOOKUP(BP28,'DIA 8'!$B$59:$C$126,2,0) -> 0 | BR28: =$BQ$8-BQ28 -> 0 | BT28: 21 | BU28: =Partici!J35 -> 0 | BV28: =VLOOKUP(BU28,'DIA 9'!$B$59:$C$126,2,0) -> 0 | BW28: =$BV$8-BV28 -> 0 | BY28: 21 | BZ28: =Partici!K35 -> 0 | CA28: =VLOOKUP(BZ28,'DIA 10'!$B$59:$C$126,2,0) -> 0 | CB28: =$CA$8-CA28 -> 0 | CD28: 21 | CE28: =Partici!L35 -> 0 | CF28: =VLOOKUP(CE28,'DIA 11'!$B$59:$C$126,2,0) -> 0 | CG28: =$CF$8-CF28 -> 0 | CI28: 21 | CJ28: =Partici!M35 -> 0 | CK28: =VLOOKUP(CJ28,'DIA 12'!$B$59:$C$126,2,0) -> 0 | CL28: =$CK$8-CK28 -> 0 | CN28: 21 | CO28: =Partici!N35 -> 0 | CP28: =VLOOKUP(CO28,'24 12 23. CLUB'!$B$59:$C$126,2,0) -> 0 | CQ28: =$CP$8-CP28 -> 0
A29: 22 | B29: =+Partici!B22 -> SIN FE | C29: ='DIA 1'!$AC$47 -> 0 | D29: ='DIA 2'!$AC$47 -> 0 | E29: ='DIA 3'!$AC$47 -> 0 | F29: ='DIA 4'!$AC$47 -> 0 | G29: ='DIA 5'!$AC$47 -> 0 | H29: ='DIA 6'!$AC$47 -> 0 | I29: ='DIA 7'!$AC$47 -> 0 | J29: ='DIA 8'!$AC$47 -> 0 | K29: ='DIA 9'!$AC$47 -> 0 | L29: ='DIA 10'!$AC$47 -> 0 | M29: ='DIA 11'!$AC$47 -> 0 | N29: ='DIA 12'!$AC$47 -> 0 | O29: ='24 12 23. CLUB'!$AC$47 -> 0 | P29: ='Dia14'!$AC$42 -> 0 | Q29: ='Dia15'!$AC$42 -> 0 | R29: ='Dia16'!$AC$42 -> 0 | S29: ='Dia17'!$AC$42 -> 0 | T29: ='Dia18'!$AC$42 -> 0 | U29: ='Dia19'!$AC$42 -> 0 | V29: ='Dia20'!$AC$42 -> 0 | W29: =SUM(Tabla1[[#This Row],[05-mar]:[10-jul20]]) -> 0 | X29: =$W$8-Tabla1[[#This Row],[TOTAL]] -> 1.1 | Z29: SOSAMAFIA | AB29: 48.7 | AC29: 37.8 | AD29: 41.8 | AF29: 22 | AG29: =Partici!B56 -> 0 | AH29: =VLOOKUP(AG29,'DIA 1'!#REF!,2,0) -> #REF! | AI29: =$BB$8-AH29 -> #REF! | AK29: 22 | AL29: =Partici!C56 -> 0 | AM29: =VLOOKUP(AL29,'DIA 2'!$B$59:$C$126,2,0) -> 0 | AN29: =$BG$8-AM29 -> 0 | AP29: 22 | AQ29: =Partici!D57 -> 0 | AR29: =VLOOKUP(AQ29,'DIA 3'!$B$59:$C$126,2,0) -> 0 | AS29: =$AR$8-AR29 -> 0 | AU29: 22 | AV29: =Partici!E53 -> 0 | AW29: =VLOOKUP(AV29,'DIA 4'!$B$59:$C$126,2,0) -> 0 | AX29: =$AW$8-AW29 -> 0 | AZ29: 22 | BA29: =Partici!F41 -> 0 | BB29: =VLOOKUP(BA29,'DIA 5'!$B$59:$C$126,2,0) -> 0 | BC29: =$BB$8-BB29 -> 0 | BE29: 22 | BF29: =Partici!G41 -> 0 | BG29: =VLOOKUP(BF29,'DIA 6'!$B$59:$C$126,2,0) -> 0 | BH29: =$BG$8-BG29 -> 0 | BJ29: 22 | BK29: =Partici!H41 -> 0 | BL29: =VLOOKUP(BK29,'DIA 7'!$B$59:$C$126,2,0) -> 0 | BM29: =$BL$8-BL29 -> 0 | BO29: 22 | BP29: =Partici!I41 -> 0 | BQ29: =VLOOKUP(BP29,'DIA 8'!$B$59:$C$126,2,0) -> 0 | BR29: =$BQ$8-BQ29 -> 0 | BT29: 22 | BU29: =Partici!J41 -> 0 | BV29: =VLOOKUP(BU29,'DIA 9'!$B$59:$C$126,2,0) -> 0 | BW29: =$BV$8-BV29 -> 0 | BY29: 22 | BZ29: =Partici!K41 -> 0 | CA29: =VLOOKUP(BZ29,'DIA 10'!$B$59:$C$126,2,0) -> 0 | CB29: =$CA$8-CA29 -> 0 | CD29: 22 | CE29: =Partici!L41 -> 0 | CF29: =VLOOKUP(CE29,'DIA 11'!$B$59:$C$126,2,0) -> 0 | CG29: =$CF$8-CF29 -> 0 | CI29: 22 | CJ29: =Partici!M41 -> 0 | CK29: =VLOOKUP(CJ29,'DIA 12'!$B$59:$C$126,2,0) -> 0 | CL29: =$CK$8-CK29 -> 0 | CN29: 22 | CO29: =Partici!N41 -> 0 | CP29: =VLOOKUP(CO29,'24 12 23. CLUB'!$B$59:$C$126,2,0) -> 0 | CQ29: =$CP$8-CP29 -> 0
A30: 23 | B30: =+Partici!B24 -> NANO | C30: ='DIA 1'!$AC$51 -> 0 | D30: ='DIA 2'!$AC$51 -> 0 | E30: ='DIA 3'!$AC$51 -> 0 | F30: ='DIA 4'!$AC$51 -> 0 | G30: ='DIA 5'!$AC$51 -> 0 | H30: ='DIA 6'!$AC$51 -> 0 | I30: ='DIA 7'!$AC$51 -> 0 | J30: ='DIA 8'!$AC$51 -> 0 | K30: ='DIA 9'!$AC$51 -> 0 | L30: ='DIA 10'!$AC$51 -> 0 | M30: ='DIA 11'!$AC$51 -> 0 | N30: ='DIA 12'!$AC$51 -> 0 | O30: ='24 12 23. CLUB'!$AC$51 -> 0 | P30: ='Dia14'!$AC$46 -> 0 | Q30: ='Dia15'!$AC$46 -> 0 | R30: ='Dia16'!$AC$46 -> 0 | S30: ='Dia17'!$AC$46 -> 0 | T30: ='Dia18'!$AC$46 -> 0 | U30: ='Dia19'!$AC$46 -> 0 | V30: ='Dia20'!$AC$46 -> 0 | W30: =SUM(Tabla1[[#This Row],[05-mar]:[10-jul20]]) -> 0 | X30: =$W$8-Tabla1[[#This Row],[TOTAL]] -> 1.1 | Z30: EOBART THAWNE | AA30: 25.7 | AB30: 27.6 | AC30: 17.7 | AD30: 31.5 | AF30: 23 | AG30: =Partici!B57 -> 0 | AH30: =VLOOKUP(AG30,'DIA 1'!#REF!,2,0) -> #REF! | AI30: =$BB$8-AH30 -> #REF! | AK30: 23 | AL30: =Partici!C57 -> 0 | AM30: =VLOOKUP(AL30,'DIA 2'!$B$59:$C$126,2,0) -> 0 | AN30: =$BG$8-AM30 -> 0 | AP30: 23 | AQ30: =Partici!D50 -> 0 | AR30: =VLOOKUP(AQ30,'DIA 3'!$B$59:$C$126,2,0) -> 0 | AS30: =$AR$8-AR30 -> 0 | AU30: 23 | AV30: =Partici!E57 -> 0 | AW30: =VLOOKUP(AV30,'DIA 4'!$B$59:$C$126,2,0) -> 0 | AX30: =$AW$8-AW30 -> 0 | AZ30: 23 | BA30: =Partici!F57 -> 0 | BB30: =VLOOKUP(BA30,'DIA 5'!$B$59:$C$126,2,0) -> 0 | BC30: =$BB$8-BB30 -> 0 | BE30: 23 | BF30: =Partici!G57 -> 0 | BG30: =VLOOKUP(BF30,'DIA 6'!$B$59:$C$126,2,0) -> 0 | BH30: =$BG$8-BG30 -> 0 | BJ30: 23 | BK30: =Partici!H57 -> 0 | BL30: =VLOOKUP(BK30,'DIA 7'!$B$59:$C$126,2,0) -> 0 | BM30: =$BL$8-BL30 -> 0 | BO30: 23 | BP30: =Partici!I57 -> 0 | BQ30: =VLOOKUP(BP30,'DIA 8'!$B$59:$C$126,2,0) -> 0 | BR30: =$BQ$8-BQ30 -> 0 | BT30: 23 | BU30: =Partici!J57 -> 0 | BV30: =VLOOKUP(BU30,'DIA 9'!$B$59:$C$126,2,0) -> 0 | BW30: =$BV$8-BV30 -> 0 | BY30: 23 | BZ30: =Partici!K57 -> 0 | CA30: =VLOOKUP(BZ30,'DIA 10'!$B$59:$C$126,2,0) -> 0 | CB30: =$CA$8-CA30 -> 0 | CD30: 23 | CE30: =Partici!L57 -> 0 | CF30: =VLOOKUP(CE30,'DIA 11'!$B$59:$C$126,2,0) -> 0 | CG30: =$CF$8-CF30 -> 0 | CI30: 23 | CJ30: =Partici!M57 -> 0 | CK30: =VLOOKUP(CJ30,'DIA 12'!$B$59:$C$126,2,0) -> 0 | CL30: =$CK$8-CK30 -> 0 | CN30: 23 | CO30: =Partici!N57 -> 0 | CP30: =VLOOKUP(CO30,'24 12 23. CLUB'!$B$59:$C$126,2,0) -> 0 | CQ30: =$CP$8-CP30 -> 0
A31: 24 | B31: =+Partici!B25 -> PINKY | C31: ='DIA 1'!$AC$53 -> 9.7 | D31: ='DIA 2'!$AC$53 -> 0 | E31: ='DIA 3'!$AC$53 -> 0 | F31: ='DIA 4'!$AC$53 -> 0 | G31: ='DIA 5'!$AC$53 -> 0 | H31: ='DIA 6'!$AC$53 -> 0 | I31: ='DIA 7'!$AC$53 -> 0 | J31: ='DIA 8'!$AC$53 -> 0 | K31: ='DIA 9'!$AC$53 -> 0 | L31: ='DIA 10'!$AC$53 -> 0 | M31: ='DIA 11'!$AC$53 -> 0 | N31: ='DIA 12'!$AC$53 -> 0 | O31: ='24 12 23. CLUB'!$AC$53 -> 0 | P31: ='Dia14'!$AC$48 -> 0 | Q31: ='Dia15'!$AC$48 -> 0 | R31: ='Dia16'!$AC$48 -> 0 | S31: ='Dia17'!$AC$48 -> 0 | T31: ='Dia18'!$AC$48 -> 0 | U31: ='Dia19'!$AC$48 -> 0 | V31: ='Dia20'!$AC$48 -> 0 | W31: =SUM(Tabla1[[#This Row],[05-mar]:[10-jul20]]) -> 9.7 | X31: =$W$8-Tabla1[[#This Row],[TOTAL]] -> -8.6 | AF31: 24 | AG31: =Partici!B58 -> 0 | AH31: =VLOOKUP(AG31,'DIA 1'!#REF!,2,0) -> #REF! | AI31: =$BB$8-AH31 -> #REF! | AK31: 24 | AL31: =Partici!C58 -> 0 | AM31: =VLOOKUP(AL31,'DIA 2'!$B$59:$C$126,2,0) -> 0 | AN31: =$BG$8-AM31 -> 0 | AP31: 24 | AQ31: =Partici!D56 -> 0 | AR31: =VLOOKUP(AQ31,'DIA 3'!$B$59:$C$126,2,0) -> 0 | AS31: =$AR$8-AR31 -> 0 | AU31: 24 | AV31: =Partici!E58 -> 0 | AW31: =VLOOKUP(AV31,'DIA 4'!$B$59:$C$126,2,0) -> 0 | AX31: =$AW$8-AW31 -> 0 | AZ31: 24 | BA31: =Partici!F58 -> 0 | BB31: =VLOOKUP(BA31,'DIA 5'!$B$59:$C$126,2,0) -> 0 | BC31: =$BB$8-BB31 -> 0 | BE31: 24 | BF31: =Partici!G58 -> 0 | BG31: =VLOOKUP(BF31,'DIA 6'!$B$59:$C$126,2,0) -> 0 | BH31: =$BG$8-BG31 -> 0 | BJ31: 24 | BK31: =Partici!H58 -> 0 | BL31: =VLOOKUP(BK31,'DIA 7'!$B$59:$C$126,2,0) -> 0 | BM31: =$BL$8-BL31 -> 0 | BO31: 24 | BP31: =Partici!I58 -> 0 | BQ31: =VLOOKUP(BP31,'DIA 8'!$B$59:$C$126,2,0) -> 0 | BR31: =$BQ$8-BQ31 -> 0 | BT31: 24 | BU31: =Partici!J58 -> 0 | BV31: =VLOOKUP(BU31,'DIA 9'!$B$59:$C$126,2,0) -> 0 | BW31: =$BV$8-BV31 -> 0 | BY31: 24 | BZ31: =Partici!K58 -> 0 | CA31: =VLOOKUP(BZ31,'DIA 10'!$B$59:$C$126,2,0) -> 0 | CB31: =$CA$8-CA31 -> 0 | CD31: 24 | CE31: =Partici!L58 -> 0 | CF31: =VLOOKUP(CE31,'DIA 11'!$B$59:$C$126,2,0) -> 0 | CG31: =$CF$8-CF31 -> 0 | CI31: 24 | CJ31: =Partici!M58 -> 0 | CK31: =VLOOKUP(CJ31,'DIA 12'!$B$59:$C$126,2,0) -> 0 | CL31: =$CK$8-CK31 -> 0 | CN31: 24 | CO31: =Partici!N58 -> 0 | CP31: =VLOOKUP(CO31,'24 12 23. CLUB'!$B$59:$C$126,2,0) -> 0 | CQ31: =$CP$8-CP31 -> 0
A32: 25 | B32: =+Partici!B26 -> ROMATRI | C32: ='DIA 1'!$AC$55 -> 3.9 | D32: ='DIA 2'!$AC$53 -> 0 | E32: ='DIA 3'!$AC$53 -> 0 | F32: ='DIA 4'!$AC$53 -> 0 | G32: ='DIA 5'!$AC$53 -> 0 | H32: ='DIA 6'!$AC$53 -> 0 | I32: ='DIA 7'!$AC$53 -> 0 | J32: ='DIA 8'!$AC$53 -> 0 | K32: ='DIA 9'!$AC$53 -> 0 | L32: ='DIA 10'!$AC$53 -> 0 | M32: ='DIA 11'!$AC$53 -> 0 | N32: ='DIA 12'!$AC$53 -> 0 | O32: ='24 12 23. CLUB'!$AC$53 -> 0 | P32: ='Dia14'!$AC$48 -> 0 | Q32: ='Dia15'!$AC$48 -> 0 | R32: ='Dia16'!$AC$48 -> 0 | S32: ='Dia17'!$AC$48 -> 0 | T32: ='Dia18'!$AC$48 -> 0 | U32: ='Dia19'!$AC$48 -> 0 | V32: ='Dia20'!$AC$48 -> 0 | W32: =SUM(Tabla1[[#This Row],[05-mar]:[10-jul20]]) -> 3.9 | X32: =$W$8-Tabla1[[#This Row],[TOTAL]] -> -2.8
A33: 26 | B33: =+Partici!B27 -> PASASTE BANDIDO | C33: ='DIA 1'!$AC$57 -> 0 | D33: ='DIA 2'!$AC$53 -> 0 | E33: ='DIA 3'!$AC$53 -> 0 | F33: ='DIA 4'!$AC$53 -> 0 | G33: ='DIA 5'!$AC$53 -> 0 | H33: ='DIA 6'!$AC$53 -> 0 | I33: ='DIA 7'!$AC$53 -> 0 | J33: ='DIA 8'!$AC$53 -> 0 | K33: ='DIA 9'!$AC$53 -> 0 | L33: ='DIA 10'!$AC$53 -> 0 | M33: ='DIA 11'!$AC$53 -> 0 | N33: ='DIA 12'!$AC$53 -> 0 | O33: ='24 12 23. CLUB'!$AC$53 -> 0 | P33: ='Dia14'!$AC$48 -> 0 | Q33: ='Dia15'!$AC$48 -> 0 | R33: ='Dia16'!$AC$48 -> 0 | S33: ='Dia17'!$AC$48 -> 0 | T33: ='Dia18'!$AC$48 -> 0 | U33: ='Dia19'!$AC$48 -> 0 | V33: ='Dia20'!$AC$48 -> 0 | W33: =SUM(Tabla1[[#This Row],[05-mar]:[10-jul20]]) -> 0 | X33: =$W$8-Tabla1[[#This Row],[TOTAL]] -> 1.1
